Workbook

Sheet Start Here
A1: THE CALLED — CLIENT TRACKER
A2: One sheet. Fill it in daily, and your numbers tell you exactly what to fix.
B4: What this is
B5: Your whole game in one place: the work you put in (posts, stories, DMs) and what it turns into (replies, calls, closes, cash). Everything on the KPI Dashboard is calculated for you — you never type a number twice.
A9: YOUR THREE JOBS
A10: Every day (60 seconds) | C10: Open Daily Log, find today's row, fill in what you did.
A11: Every Sunday (2 minutes) | C11: Open Instagram Tracker, log this week's numbers from your Professional Dashboard.
A12: Every month (1 minute) | C12: Drop a profile + insights screenshot at the top of Instagram Tracker so your coach can audit your page.
A14: WHAT EACH TAB IS FOR
B15: Tab | C15: What it's for | D15: Do you type here?
B16: Daily Log | C16: One row per day. The only place your daily numbers get entered. | D16: YES — every day
B17: KPI Dashboard | C17: Auto totals, conversion rates and charts for this week, this month and all time. | D17: No — it's automatic
B18: Instagram Tracker | C18: Weekly follower and reach numbers, plus your monthly profile screenshots. | D18: YES — weekly
B19: Weekly Rollup | C19: Feeds the dashboard charts — your last 13 weeks, week by week. | D19: No — it's automatic
B20: Setup | C20: Your name, start date and daily standards. Set once at the start. | D20: YES — once
A22: THE RULES (read once, saves you a headache)
B23: • | C23: Cream cells = you type here. Grey cells = calculated, leave them alone.
B24: • | C24: Don't delete columns or rows — it breaks the maths. If you don't use a column, right-click and Hide it.
B25: • | C25: One row per day, in date order. Log a zero day as 0, not blank — blank means 'didn't track'.
B26: • | C26: Miss a day? Backfill it. A gap makes your averages look better than they are.
A28: EXAMPLE — what one good day looks like in the Daily Log
B29: Date | C29: Reels | D29: Stories | E29: Opener DMs | F29: Follow-Ups | G29: Replies | H29: Pitched
B30: Mon 15 Sep | C30: 4 | D30: 30 | E30: 10 | F30: 10 | G30: 6 | H30: 3
B31: All four standards hit → that day scores 4/4 and turns green.
A33: WALKTHROUGH VIDEOS
A34: Daily Log walkthrough | C34: [paste Loom link]
A35: KPI Dashboard walkthrough | C35: [paste Loom link]
A36: Instagram Tracker walkthrough | C36: [paste Loom link]

Sheet Setup
A1: SETUP — fill this in once
A2: Cream cells are yours to fill. Everything in the workbook reads from here.
A4: CLIENT DETAILS
B5: Client name | C5: Demo Client | D5: Your name — shows on the dashboard.
B6: Coach / CSM | C6: Francis | D6: Who you report to inside The Called.
B7: Instagram handle | C7: @democlient | D7: e.g. @yourhandle
B8: Tracking start date | C8: =TODAY()-45 | D8: Day 1. This sets every date in the Daily Log.
B9: First tracking week (auto) | C9: =C8-WEEKDAY(C8,2)+1 | D9: Monday of your start week. Calculated — don't edit.
A11: DAILY STANDARDS — the minimum you hold yourself to
B12: Reels / posts per day | C12: 4 | D12: Default 4.
B13: Stories per day | C13: 30 | D13: Default 30.
B14: Opener DMs per day | C14: 10 | D14: Default 10.
B15: Follow-up DMs per day | C15: 10 | D15: Default 10.
A17: GOALS
B18: Monthly cash collected goal | C18: 10000 | D18: Drives the goal box on the dashboard.
B19: Your offer price | C19: 0 | D19: Optional — for your own maths.

Sheet Daily Log
A1: DAILY LOG — one row per day
A2: Daily standard → | C2: =Setup!$C$12 | D2: =Setup!$C$13 | E2: =Setup!$C$14 | F2: =Setup!$C$15 | H2: Fill in what you actually did. Log a zero as 0 — blank means you didn't track that day.
A3: Date | B3: Day | C3: Reels / Posts | D3: Stories | E3: Opener DMs Sent | F3: Follow-Up DMs Sent | G3: Replies | H3: Calls Pitched | I3: Calls Booked | J3: Calls Showed | K3: Closes | L3: Cash Collected | M3: Revenue Generated | N3: Followers (end of day) | O3: Standards Hit (of 4) | P3: Notes | Q3: Logged? (auto)
A4: =Setup!$C$8 | B4: =IF(A4="","",TEXT(A4,"ddd")) | C4: 5 | D4: 30 | E4: 14 | F4: 9 | G4: 3 | H4: 4 | I4: 0 | J4: 0 | K4: 0 | L4: 0 | M4: 0 | N4: 3187 | O4: =IF($Q4=0,"",IF(C4>=C$2,1,0)+IF(D4>=D$2,1,0)+IF(E4>=E$2,1,0)+IF(F4>=F$2,1,0)) | P4: First week — found my footing | Q4: =IF(COUNT(C4:M4)>0,1,0)
A5: =A4+1 | B5: =IF(A5="","",TEXT(A5,"ddd")) | C5: 6 | D5: 31 | E5: 11 | F5: 9 | G5: 6 | H5: 3 | I5: 0 | J5: 0 | K5: 0 | L5: 0 | M5: 0 | N5: 3210 | O5: =IF($Q5=0,"",IF(C5>=C$2,1,0)+IF(D5>=D$2,1,0)+IF(E5>=E$2,1,0)+IF(F5>=F$2,1,0)) | Q5: =IF(COUNT(C5:M5)>0,1,0)
A6: =A5+1 | B6: =IF(A6="","",TEXT(A6,"ddd")) | C6: 5 | D6: 28 | E6: 15 | F6: 9 | G6: 4 | H6: 4 | I6: 2 | J6: 0 | K6: 0 | L6: 0 | M6: 0 | N6: 3217 | O6: =IF($Q6=0,"",IF(C6>=C$2,1,0)+IF(D6>=D$2,1,0)+IF(E6>=E$2,1,0)+IF(F6>=F$2,1,0)) | Q6: =IF(COUNT(C6:M6)>0,1,0)
A7: =A6+1 | B7: =IF(A7="","",TEXT(A7,"ddd")) | C7: 6 | D7: 34 | E7: 11 | F7: 10 | G7: 3 | H7: 4 | I7: 0 | J7: 2 | K7: 1 | L7: 1500 | M7: 3000 | N7: 3232 | O7: =IF($Q7=0,"",IF(C7>=C$2,1,0)+IF(D7>=D$2,1,0)+IF(E7>=E$2,1,0)+IF(F7>=F$2,1,0)) | Q7: =IF(COUNT(C7:M7)>0,1,0)
A8: =A7+1 | B8: =IF(A8="","",TEXT(A8,"ddd")) | C8: 6 | D8: 30 | E8: 11 | F8: 13 | G8: 7 | H8: 4 | I8: 0 | J8: 0 | K8: 0 | L8: 0 | M8: 0 | N8: 3255 | O8: =IF($Q8=0,"",IF(C8>=C$2,1,0)+IF(D8>=D$2,1,0)+IF(E8>=E$2,1,0)+IF(F8>=F$2,1,0)) | Q8: =IF(COUNT(C8:M8)>0,1,0)
A9: =A8+1 | B9: =IF(A9="","",TEXT(A9,"ddd")) | C9: 2 | D9: 21 | E9: 4 | F9: 7 | G9: 1 | H9: 1 | I9: 1 | J9: 0 | K9: 0 | L9: 0 | M9: 0 | N9: 3275 | O9: =IF($Q9=0,"",IF(C9>=C$2,1,0)+IF(D9>=D$2,1,0)+IF(E9>=E$2,1,0)+IF(F9>=F$2,1,0)) | Q9: =IF(COUNT(C9:M9)>0,1,0)
A10: =A9+1 | B10: =IF(A10="","",TEXT(A10,"ddd")) | C10: 3 | D10: 17 | E10: 6 | F10: 4 | G10: 1 | H10: 0 | I10: 0 | J10: 1 | K10: 0 | L10: 0 | M10: 0 | N10: 3291 | O10: =IF($Q10=0,"",IF(C10>=C$2,1,0)+IF(D10>=D$2,1,0)+IF(E10>=E$2,1,0)+IF(F10>=F$2,1,0)) | Q10: =IF(COUNT(C10:M10)>0,1,0)
A11: =A10+1 | B11: =IF(A11="","",TEXT(A11,"ddd")) | C11: 6 | D11: 35 | E11: 13 | F11: 13 | G11: 3 | H11: 2 | I11: 2 | J11: 0 | K11: 0 | L11: 0 | M11: 0 | N11: 3307 | O11: =IF($Q11=0,"",IF(C11>=C$2,1,0)+IF(D11>=D$2,1,0)+IF(E11>=E$2,1,0)+IF(F11>=F$2,1,0)) | Q11: =IF(COUNT(C11:M11)>0,1,0)
A12: =A11+1 | B12: =IF(A12="","",TEXT(A12,"ddd")) | C12: 4 | D12: 35 | E12: 14 | F12: 9 | G12: 3 | H12: 4 | I12: 2 | J12: 2 | K12: 0 | L12: 0 | M12: 0 | N12: 3323 | O12: =IF($Q12=0,"",IF(C12>=C$2,1,0)+IF(D12>=D$2,1,0)+IF(E12>=E$2,1,0)+IF(F12>=F$2,1,0)) | Q12: =IF(COUNT(C12:M12)>0,1,0)
A13: =A12+1 | B13: =IF(A13="","",TEXT(A13,"ddd")) | C13: 6 | D13: 33 | E13: 15 | F13: 12 | G13: 7 | H13: 3 | I13: 0 | J13: 2 | K13: 0 | L13: 0 | M13: 0 | N13: 3344 | O13: =IF($Q13=0,"",IF(C13>=C$2,1,0)+IF(D13>=D$2,1,0)+IF(E13>=E$2,1,0)+IF(F13>=F$2,1,0)) | Q13: =IF(COUNT(C13:M13)>0,1,0)
A14: =A13+1 | B14: =IF(A14="","",TEXT(A14,"ddd")) | C14: 6 | D14: 29 | E14: 11 | F14: 11 | G14: 7 | H14: 4 | I14: 1 | J14: 0 | K14: 0 | L14: 0 | M14: 0 | N14: 3362 | O14: =IF($Q14=0,"",IF(C14>=C$2,1,0)+IF(D14>=D$2,1,0)+IF(E14>=E$2,1,0)+IF(F14>=F$2,1,0)) | Q14: =IF(COUNT(C14:M14)>0,1,0)
A15: =A14+1 | B15: =IF(A15="","",TEXT(A15,"ddd")) | C15: 6 | D15: 33 | E15: 11 | F15: 12 | G15: 5 | H15: 2 | I15: 2 | J15: 0 | K15: 0 | L15: 0 | M15: 0 | N15: 3369 | O15: =IF($Q15=0,"",IF(C15>=C$2,1,0)+IF(D15>=D$2,1,0)+IF(E15>=E$2,1,0)+IF(F15>=F$2,1,0)) | Q15: =IF(COUNT(C15:M15)>0,1,0)
A16: =A15+1 | B16: =IF(A16="","",TEXT(A16,"ddd")) | C16: 2 | D16: 16 | E16: 5 | F16: 4 | G16: 2 | H16: 1 | I16: 1 | J16: 1 | K16: 0 | L16: 0 | M16: 0 | N16: 3392 | O16: =IF($Q16=0,"",IF(C16>=C$2,1,0)+IF(D16>=D$2,1,0)+IF(E16>=E$2,1,0)+IF(F16>=F$2,1,0)) | Q16: =IF(COUNT(C16:M16)>0,1,0)
... A19: =A18+1 | B19: =IF(A19="","",TEXT(A19,"ddd")) | C19: 4 | D19: 32 | E19: 13 | F19: 9 | G19: 4 | H19: 3 | I19: 2 | J19: 0 | K19: 0 | L19: 0 | M19: 0 | N19: 3453 | O19: =IF($Q19=0,"",IF(C19>=C$2,1,0)+IF(D19>=D$2,1,0)+IF(E19>=E$2,1,0)+IF(F19>=F$2,1,0)) | Q19: =IF(COUNT(C19:M19)>0,1,0)
A20: =A19+1 | B20: =IF(A20="","",TEXT(A20,"ddd")) | C20: 0 | D20: 0 | E20: 0 | F20: 0 | G20: 0 | H20: 0 | I20: 0 | J20: 2 | K20: 1 | L20: 3000 | M20: 4500 | N20: 3453 | O20: =IF($Q20=0,"",IF(C20>=C$2,1,0)+IF(D20>=D$2,1,0)+IF(E20>=E$2,1,0)+IF(F20>=F$2,1,0)) | P20: Travel day, no work done | Q20: =IF(COUNT(C20:M20)>0,1,0)
A21: =A20+1 | B21: =IF(A21="","",TEXT(A21,"ddd")) | C21: 6 | D21: 28 | E21: 14 | F21: 13 | G21: 6 | H21: 3 | I21: 1 | J21: 0 | K21: 0 | L21: 0 | M21: 0 | N21: 3474 | O21: =IF($Q21=0,"",IF(C21>=C$2,1,0)+IF(D21>=D$2,1,0)+IF(E21>=E$2,1,0)+IF(F21>=F$2,1,0)) | Q21: =IF(COUNT(C21:M21)>0,1,0)
A22: =A21+1 | B22: =IF(A22="","",TEXT(A22,"ddd")) | C22: 6 | D22: 34 | E22: 11 | F22: 10 | G22: 3 | H22: 2 | I22: 1 | J22: 0 | K22: 0 | L22: 0 | M22: 0 | N22: 3490 | O22: =IF($Q22=0,"",IF(C22>=C$2,1,0)+IF(D22>=D$2,1,0)+IF(E22>=E$2,1,0)+IF(F22>=F$2,1,0)) | Q22: =IF(COUNT(C22:M22)>0,1,0)
A23: =A22+1 | B23: =IF(A23="","",TEXT(A23,"ddd")) | C23: 2 | D23: 13 | E23: 4 | F23: 7 | G23: 1 | H23: 0 | I23: 1 | J23: 1 | K23: 1 | L23: 1500 | M23: 3000 | N23: 3508 | O23: =IF($Q23=0,"",IF(C23>=C$2,1,0)+IF(D23>=D$2,1,0)+IF(E23>=E$2,1,0)+IF(F23>=F$2,1,0)) | Q23: =IF(COUNT(C23:M23)>0,1,0)
A24: =A23+1 | B24: =IF(A24="","",TEXT(A24,"ddd")) | C24: 2 | D24: 22 | E24: 6 | F24: 5 | G24: 3 | H24: 1 | I24: 1 | J24: 0 | K24: 0 | L24: 0 | M24: 0 | N24: 3529 | O24: =IF($Q24=0,"",IF(C24>=C$2,1,0)+IF(D24>=D$2,1,0)+IF(E24>=E$2,1,0)+IF(F24>=F$2,1,0)) | Q24: =IF(COUNT(C24:M24)>0,1,0)
A25: =A24+1 | B25: =IF(A25="","",TEXT(A25,"ddd")) | C25: 5 | D25: 35 | E25: 14 | F25: 11 | G25: 3 | H25: 2 | I25: 0 | J25: 1 | K25: 0 | L25: 0 | M25: 0 | N25: 3550 | O25: =IF($Q25=0,"",IF(C25>=C$2,1,0)+IF(D25>=D$2,1,0)+IF(E25>=E$2,1,0)+IF(F25>=F$2,1,0)) | Q25: =IF(COUNT(C25:M25)>0,1,0)
A26: =A25+1 | B26: =IF(A26="","",TEXT(A26,"ddd")) | C26: 6 | D26: 30 | E26: 15 | F26: 9 | G26: 4 | H26: 4 | I26: 1 | J26: 0 | K26: 0 | L26: 0 | M26: 0 | N26: 3573 | O26: =IF($Q26=0,"",IF(C26>=C$2,1,0)+IF(D26>=D$2,1,0)+IF(E26>=E$2,1,0)+IF(F26>=F$2,1,0)) | Q26: =IF(COUNT(C26:M26)>0,1,0)
A27: =A26+1 | B27: =IF(A27="","",TEXT(A27,"ddd")) | C27: 4 | D27: 36 | E27: 13 | F27: 9 | G27: 5 | H27: 4 | I27: 1 | J27: 1 | K27: 0 | L27: 0 | M27: 0 | N27: 3586 | O27: =IF($Q27=0,"",IF(C27>=C$2,1,0)+IF(D27>=D$2,1,0)+IF(E27>=E$2,1,0)+IF(F27>=F$2,1,0)) | Q27: =IF(COUNT(C27:M27)>0,1,0)
A28: =A27+1 | B28: =IF(A28="","",TEXT(A28,"ddd")) | C28: 6 | D28: 36 | E28: 15 | F28: 11 | G28: 4 | H28: 4 | I28: 0 | J28: 1 | K28: 0 | L28: 0 | M28: 0 | N28: 3599 | O28: =IF($Q28=0,"",IF(C28>=C$2,1,0)+IF(D28>=D$2,1,0)+IF(E28>=E$2,1,0)+IF(F28>=F$2,1,0)) | Q28: =IF(COUNT(C28:M28)>0,1,0)
A29: =A28+1 | B29: =IF(A29="","",TEXT(A29,"ddd")) | C29: 4 | D29: 36 | E29: 14 | F29: 11 | G29: 3 | H29: 2 | I29: 1 | J29: 0 | K29: 0 | L29: 0 | M29: 0 | N29: 3611 | O29: =IF($Q29=0,"",IF(C29>=C$2,1,0)+IF(D29>=D$2,1,0)+IF(E29>=E$2,1,0)+IF(F29>=F$2,1,0)) | Q29: =IF(COUNT(C29:M29)>0,1,0)
A30: =A29+1 | B30: =IF(A30="","",TEXT(A30,"ddd")) | C30: 3 | D30: 19 | E30: 6 | F30: 5 | G30: 1 | H30: 0 | I30: 0 | J30: 0 | K30: 0 | L30: 0 | M30: 0 | N30: 3623 | O30: =IF($Q30=0,"",IF(C30>=C$2,1,0)+IF(D30>=D$2,1,0)+IF(E30>=E$2,1,0)+IF(F30>=F$2,1,0)) | Q30: =IF(COUNT(C30:M30)>0,1,0)
A31: =A30+1 | B31: =IF(A31="","",TEXT(A31,"ddd")) | C31: 3 | D31: 15 | E31: 7 | F31: 7 | G31: 3 | H31: 0 | I31: 1 | J31: 0 | K31: 0 | L31: 0 | M31: 0 | N31: 3640 | O31: =IF($Q31=0,"",IF(C31>=C$2,1,0)+IF(D31>=D$2,1,0)+IF(E31>=E$2,1,0)+IF(F31>=F$2,1,0)) | Q31: =IF(COUNT(C31:M31)>0,1,0)
A32: =A31+1 | B32: =IF(A32="","",TEXT(A32,"ddd")) | C32: 6 | D32: 29 | E32: 16 | F32: 9 | G32: 6 | H32: 4 | I32: 0 | J32: 1 | K32: 1 | L32: 3000 | M32: 3000 | N32: 3648 | O32: =IF($Q32=0,"",IF(C32>=C$2,1,0)+IF(D32>=D$2,1,0)+IF(E32>=E$2,1,0)+IF(F32>=F$2,1,0)) | Q32: =IF(COUNT(C32:M32)>0,1,0)
... A48: =A47+1 | B48: =IF(A48="","",TEXT(A48,"ddd")) | C48: 6 | D48: 33 | E48: 11 | F48: 11 | G48: 7 | H48: 3 | I48: 1 | J48: 0 | K48: 0 | L48: 0 | M48: 0 | N48: 3850 | O48: =IF($Q48=0,"",IF(C48>=C$2,1,0)+IF(D48>=D$2,1,0)+IF(E48>=E$2,1,0)+IF(F48>=F$2,1,0)) | Q48: =IF(COUNT(C48:M48)>0,1,0)
A49: =A48+1 | B49: =IF(A49="","",TEXT(A49,"ddd")) | O49: =IF($Q49=0,"",IF(C49>=C$2,1,0)+IF(D49>=D$2,1,0)+IF(E49>=E$2,1,0)+IF(F49>=F$2,1,0)) | Q49: =IF(COUNT(C49:M49)>0,1,0)
A50: =A49+1 | B50: =IF(A50="","",TEXT(A50,"ddd")) | O50: =IF($Q50=0,"",IF(C50>=C$2,1,0)+IF(D50>=D$2,1,0)+IF(E50>=E$2,1,0)+IF(F50>=F$2,1,0)) | Q50: =IF(COUNT(C50:M50)>0,1,0)
A51: =A50+1 | B51: =IF(A51="","",TEXT(A51,"ddd")) | O51: =IF($Q51=0,"",IF(C51>=C$2,1,0)+IF(D51>=D$2,1,0)+IF(E51>=E$2,1,0)+IF(F51>=F$2,1,0)) | Q51: =IF(COUNT(C51:M51)>0,1,0)
A52: =A51+1 | B52: =IF(A52="","",TEXT(A52,"ddd")) | O52: =IF($Q52=0,"",IF(C52>=C$2,1,0)+IF(D52>=D$2,1,0)+IF(E52>=E$2,1,0)+IF(F52>=F$2,1,0)) | Q52: =IF(COUNT(C52:M52)>0,1,0)
A53: =A52+1 | B53: =IF(A53="","",TEXT(A53,"ddd")) | O53: =IF($Q53=0,"",IF(C53>=C$2,1,0)+IF(D53>=D$2,1,0)+IF(E53>=E$2,1,0)+IF(F53>=F$2,1,0)) | Q53: =IF(COUNT(C53:M53)>0,1,0)
A54: =A53+1 | B54: =IF(A54="","",TEXT(A54,"ddd")) | O54: =IF($Q54=0,"",IF(C54>=C$2,1,0)+IF(D54>=D$2,1,0)+IF(E54>=E$2,1,0)+IF(F54>=F$2,1,0)) | Q54: =IF(COUNT(C54:M54)>0,1,0)
A55: =A54+1 | B55: =IF(A55="","",TEXT(A55,"ddd")) | O55: =IF($Q55=0,"",IF(C55>=C$2,1,0)+IF(D55>=D$2,1,0)+IF(E55>=E$2,1,0)+IF(F55>=F$2,1,0)) | Q55: =IF(COUNT(C55:M55)>0,1,0)
A56: =A55+1 | B56: =IF(A56="","",TEXT(A56,"ddd")) | O56: =IF($Q56=0,"",IF(C56>=C$2,1,0)+IF(D56>=D$2,1,0)+IF(E56>=E$2,1,0)+IF(F56>=F$2,1,0)) | Q56: =IF(COUNT(C56:M56)>0,1,0)
A57: =A56+1 | B57: =IF(A57="","",TEXT(A57,"ddd")) | O57: =IF($Q57=0,"",IF(C57>=C$2,1,0)+IF(D57>=D$2,1,0)+IF(E57>=E$2,1,0)+IF(F57>=F$2,1,0)) | Q57: =IF(COUNT(C57:M57)>0,1,0)
...

Sheet KPI Dashboard
A1: KPI DASHBOARD
A2: 100% automatic — it reads your Daily Log. If a number looks wrong, the fix is in the Daily Log.
B4: This Week | C4: Last Week | D4: This Month | E4: Last Month | F4: All Time | H4: THIS MONTH vs GOAL
B5: =TEXT(B6,"d mmm")&" – "&TEXT(B7,"d mmm") | C5: =TEXT(C6,"d mmm")&" – "&TEXT(C7,"d mmm") | D5: =TEXT(D6,"d mmm")&" – "&TEXT(D7,"d mmm") | E5: =TEXT(E6,"d mmm")&" – "&TEXT(E7,"d mmm") | F5: =TEXT(F6,"d mmm")&" – "&TEXT(F7,"d mmm") | H5: Cash goal | J5: =Setup!$C$18
A6: Period start | B6: =TODAY()-WEEKDAY(TODAY(),2)+1 | C6: =B6-7 | D6: =DATE(YEAR(TODAY()),MONTH(TODAY()),1) | E6: =EOMONTH(TODAY(),-2)+1 | F6: =Setup!$C$8 | H6: Collected so far | J6: =D23
A7: Period end | B7: =TODAY() | C7: =B6-1 | D7: =TODAY() | E7: =EOMONTH(TODAY(),-1) | F7: =TODAY() | H7: % of goal | J7: =IFERROR(D23/Setup!$C$18,"")
H8: Days left in month | J8: =EOMONTH(TODAY(),0)-TODAY()
A9: ACTIVITY — what you put in
A10: Days Logged | B10: =SUMIFS('Daily Log'!$Q$4:$Q$369,'Daily Log'!$A$4:$A$369,">="&B$6,'Daily Log'!$A$4:$A$369,"<="&B$7) | C10: =SUMIFS('Daily Log'!$Q$4:$Q$369,'Daily Log'!$A$4:$A$369,">="&C$6,'Daily Log'!$A$4:$A$369,"<="&C$7) | D10: =SUMIFS('Daily Log'!$Q$4:$Q$369,'Daily Log'!$A$4:$A$369,">="&D$6,'Daily Log'!$A$4:$A$369,"<="&D$7) | E10: =SUMIFS('Daily Log'!$Q$4:$Q$369,'Daily Log'!$A$4:$A$369,">="&E$6,'Daily Log'!$A$4:$A$369,"<="&E$7) | F10: =SUMIFS('Daily Log'!$Q$4:$Q$369,'Daily Log'!$A$4:$A$369,">="&F$6,'Daily Log'!$A$4:$A$369,"<="&F$7)
A11: Reels / Posts | B11: =SUMIFS('Daily Log'!$C$4:$C$369,'Daily Log'!$A$4:$A$369,">="&B$6,'Daily Log'!$A$4:$A$369,"<="&B$7) | C11: =SUMIFS('Daily Log'!$C$4:$C$369,'Daily Log'!$A$4:$A$369,">="&C$6,'Daily Log'!$A$4:$A$369,"<="&C$7) | D11: =SUMIFS('Daily Log'!$C$4:$C$369,'Daily Log'!$A$4:$A$369,">="&D$6,'Daily Log'!$A$4:$A$369,"<="&D$7) | E11: =SUMIFS('Daily Log'!$C$4:$C$369,'Daily Log'!$A$4:$A$369,">="&E$6,'Daily Log'!$A$4:$A$369,"<="&E$7) | F11: =SUMIFS('Daily Log'!$C$4:$C$369,'Daily Log'!$A$4:$A$369,">="&F$6,'Daily Log'!$A$4:$A$369,"<="&F$7)
A12: Stories | B12: =SUMIFS('Daily Log'!$D$4:$D$369,'Daily Log'!$A$4:$A$369,">="&B$6,'Daily Log'!$A$4:$A$369,"<="&B$7) | C12: =SUMIFS('Daily Log'!$D$4:$D$369,'Daily Log'!$A$4:$A$369,">="&C$6,'Daily Log'!$A$4:$A$369,"<="&C$7) | D12: =SUMIFS('Daily Log'!$D$4:$D$369,'Daily Log'!$A$4:$A$369,">="&D$6,'Daily Log'!$A$4:$A$369,"<="&D$7) | E12: =SUMIFS('Daily Log'!$D$4:$D$369,'Daily Log'!$A$4:$A$369,">="&E$6,'Daily Log'!$A$4:$A$369,"<="&E$7) | F12: =SUMIFS('Daily Log'!$D$4:$D$369,'Daily Log'!$A$4:$A$369,">="&F$6,'Daily Log'!$A$4:$A$369,"<="&F$7)
A13: Opener DMs Sent | B13: =SUMIFS('Daily Log'!$E$4:$E$369,'Daily Log'!$A$4:$A$369,">="&B$6,'Daily Log'!$A$4:$A$369,"<="&B$7) | C13: =SUMIFS('Daily Log'!$E$4:$E$369,'Daily Log'!$A$4:$A$369,">="&C$6,'Daily Log'!$A$4:$A$369,"<="&C$7) | D13: =SUMIFS('Daily Log'!$E$4:$E$369,'Daily Log'!$A$4:$A$369,">="&D$6,'Daily Log'!$A$4:$A$369,"<="&D$7) | E13: =SUMIFS('Daily Log'!$E$4:$E$369,'Daily Log'!$A$4:$A$369,">="&E$6,'Daily Log'!$A$4:$A$369,"<="&E$7) | F13: =SUMIFS('Daily Log'!$E$4:$E$369,'Daily Log'!$A$4:$A$369,">="&F$6,'Daily Log'!$A$4:$A$369,"<="&F$7)
A14: Follow-Up DMs Sent | B14: =SUMIFS('Daily Log'!$F$4:$F$369,'Daily Log'!$A$4:$A$369,">="&B$6,'Daily Log'!$A$4:$A$369,"<="&B$7) | C14: =SUMIFS('Daily Log'!$F$4:$F$369,'Daily Log'!$A$4:$A$369,">="&C$6,'Daily Log'!$A$4:$A$369,"<="&C$7) | D14: =SUMIFS('Daily Log'!$F$4:$F$369,'Daily Log'!$A$4:$A$369,">="&D$6,'Daily Log'!$A$4:$A$369,"<="&D$7) | E14: =SUMIFS('Daily Log'!$F$4:$F$369,'Daily Log'!$A$4:$A$369,">="&E$6,'Daily Log'!$A$4:$A$369,"<="&E$7) | F14: =SUMIFS('Daily Log'!$F$4:$F$369,'Daily Log'!$A$4:$A$369,">="&F$6,'Daily Log'!$A$4:$A$369,"<="&F$7)
A15: Total DMs Sent | B15: =B13+B14 | C15: =C13+C14 | D15: =D13+D14 | E15: =E13+E14 | F15: =F13+F14
A16: Replies | B16: =SUMIFS('Daily Log'!$G$4:$G$369,'Daily Log'!$A$4:$A$369,">="&B$6,'Daily Log'!$A$4:$A$369,"<="&B$7) | C16: =SUMIFS('Daily Log'!$G$4:$G$369,'Daily Log'!$A$4:$A$369,">="&C$6,'Daily Log'!$A$4:$A$369,"<="&C$7) | D16: =SUMIFS('Daily Log'!$G$4:$G$369,'Daily Log'!$A$4:$A$369,">="&D$6,'Daily Log'!$A$4:$A$369,"<="&D$7) | E16: =SUMIFS('Daily Log'!$G$4:$G$369,'Daily Log'!$A$4:$A$369,">="&E$6,'Daily Log'!$A$4:$A$369,"<="&E$7) | F16: =SUMIFS('Daily Log'!$G$4:$G$369,'Daily Log'!$A$4:$A$369,">="&F$6,'Daily Log'!$A$4:$A$369,"<="&F$7)
A18: SALES — what it turned into
A19: Calls Pitched | B19: =SUMIFS('Daily Log'!$H$4:$H$369,'Daily Log'!$A$4:$A$369,">="&B$6,'Daily Log'!$A$4:$A$369,"<="&B$7) | C19: =SUMIFS('Daily Log'!$H$4:$H$369,'Daily Log'!$A$4:$A$369,">="&C$6,'Daily Log'!$A$4:$A$369,"<="&C$7) | D19: =SUMIFS('Daily Log'!$H$4:$H$369,'Daily Log'!$A$4:$A$369,">="&D$6,'Daily Log'!$A$4:$A$369,"<="&D$7) | E19: =SUMIFS('Daily Log'!$H$4:$H$369,'Daily Log'!$A$4:$A$369,">="&E$6,'Daily Log'!$A$4:$A$369,"<="&E$7) | F19: =SUMIFS('Daily Log'!$H$4:$H$369,'Daily Log'!$A$4:$A$369,">="&F$6,'Daily Log'!$A$4:$A$369,"<="&F$7)
A20: Calls Booked | B20: =SUMIFS('Daily Log'!$I$4:$I$369,'Daily Log'!$A$4:$A$369,">="&B$6,'Daily Log'!$A$4:$A$369,"<="&B$7) | C20: =SUMIFS('Daily Log'!$I$4:$I$369,'Daily Log'!$A$4:$A$369,">="&C$6,'Daily Log'!$A$4:$A$369,"<="&C$7) | D20: =SUMIFS('Daily Log'!$I$4:$I$369,'Daily Log'!$A$4:$A$369,">="&D$6,'Daily Log'!$A$4:$A$369,"<="&D$7) | E20: =SUMIFS('Daily Log'!$I$4:$I$369,'Daily Log'!$A$4:$A$369,">="&E$6,'Daily Log'!$A$4:$A$369,"<="&E$7) | F20: =SUMIFS('Daily Log'!$I$4:$I$369,'Daily Log'!$A$4:$A$369,">="&F$6,'Daily Log'!$A$4:$A$369,"<="&F$7)
A21: Calls Showed | B21: =SUMIFS('Daily Log'!$J$4:$J$369,'Daily Log'!$A$4:$A$369,">="&B$6,'Daily Log'!$A$4:$A$369,"<="&B$7) | C21: =SUMIFS('Daily Log'!$J$4:$J$369,'Daily Log'!$A$4:$A$369,">="&C$6,'Daily Log'!$A$4:$A$369,"<="&C$7) | D21: =SUMIFS('Daily Log'!$J$4:$J$369,'Daily Log'!$A$4:$A$369,">="&D$6,'Daily Log'!$A$4:$A$369,"<="&D$7) | E21: =SUMIFS('Daily Log'!$J$4:$J$369,'Daily Log'!$A$4:$A$369,">="&E$6,'Daily Log'!$A$4:$A$369,"<="&E$7) | F21: =SUMIFS('Daily Log'!$J$4:$J$369,'Daily Log'!$A$4:$A$369,">="&F$6,'Daily Log'!$A$4:$A$369,"<="&F$7)
A22: Closes | B22: =SUMIFS('Daily Log'!$K$4:$K$369,'Daily Log'!$A$4:$A$369,">="&B$6,'Daily Log'!$A$4:$A$369,"<="&B$7) | C22: =SUMIFS('Daily Log'!$K$4:$K$369,'Daily Log'!$A$4:$A$369,">="&C$6,'Daily Log'!$A$4:$A$369,"<="&C$7) | D22: =SUMIFS('Daily Log'!$K$4:$K$369,'Daily Log'!$A$4:$A$369,">="&D$6,'Daily Log'!$A$4:$A$369,"<="&D$7) | E22: =SUMIFS('Daily Log'!$K$4:$K$369,'Daily Log'!$A$4:$A$369,">="&E$6,'Daily Log'!$A$4:$A$369,"<="&E$7) | F22: =SUMIFS('Daily Log'!$K$4:$K$369,'Daily Log'!$A$4:$A$369,">="&F$6,'Daily Log'!$A$4:$A$369,"<="&F$7)
A23: Cash Collected | B23: =SUMIFS('Daily Log'!$L$4:$L$369,'Daily Log'!$A$4:$A$369,">="&B$6,'Daily Log'!$A$4:$A$369,"<="&B$7) | C23: =SUMIFS('Daily Log'!$L$4:$L$369,'Daily Log'!$A$4:$A$369,">="&C$6,'Daily Log'!$A$4:$A$369,"<="&C$7) | D23: =SUMIFS('Daily Log'!$L$4:$L$369,'Daily Log'!$A$4:$A$369,">="&D$6,'Daily Log'!$A$4:$A$369,"<="&D$7) | E23: =SUMIFS('Daily Log'!$L$4:$L$369,'Daily Log'!$A$4:$A$369,">="&E$6,'Daily Log'!$A$4:$A$369,"<="&E$7) | F23: =SUMIFS('Daily Log'!$L$4:$L$369,'Daily Log'!$A$4:$A$369,">="&F$6,'Daily Log'!$A$4:$A$369,"<="&F$7)
A24: Revenue Generated | B24: =SUMIFS('Daily Log'!$M$4:$M$369,'Daily Log'!$A$4:$A$369,">="&B$6,'Daily Log'!$A$4:$A$369,"<="&B$7) | C24: =SUMIFS('Daily Log'!$M$4:$M$369,'Daily Log'!$A$4:$A$369,">="&C$6,'Daily Log'!$A$4:$A$369,"<="&C$7) | D24: =SUMIFS('Daily Log'!$M$4:$M$369,'Daily Log'!$A$4:$A$369,">="&D$6,'Daily Log'!$A$4:$A$369,"<="&D$7) | E24: =SUMIFS('Daily Log'!$M$4:$M$369,'Daily Log'!$A$4:$A$369,">="&E$6,'Daily Log'!$A$4:$A$369,"<="&E$7) | F24: =SUMIFS('Daily Log'!$M$4:$M$369,'Daily Log'!$A$4:$A$369,">="&F$6,'Daily Log'!$A$4:$A$369,"<="&F$7)
A26: CONVERSION RATES — where you're actually leaking
A27: Reply Rate (replies ÷ DMs sent) | B27: =IFERROR(B16/B15,"") | C27: =IFERROR(C16/C15,"") | D27: =IFERROR(D16/D15,"") | E27: =IFERROR(E16/E15,"") | F27: =IFERROR(F16/F15,"")
A28: Pitch Rate (pitched ÷ replies) | B28: =IFERROR(B19/B16,"") | C28: =IFERROR(C19/C16,"") | D28: =IFERROR(D19/D16,"") | E28: =IFERROR(E19/E16,"") | F28: =IFERROR(F19/F16,"")
A29: Book Rate (booked ÷ pitched) | B29: =IFERROR(B20/B19,"") | C29: =IFERROR(C20/C19,"") | D29: =IFERROR(D20/D19,"") | E29: =IFERROR(E20/E19,"") | F29: =IFERROR(F20/F19,"")
A30: Show Rate (showed ÷ booked) | B30: =IFERROR(B21/B20,"") | C30: =IFERROR(C21/C20,"") | D30: =IFERROR(D21/D20,"") | E30: =IFERROR(E21/E20,"") | F30: =IFERROR(F21/F20,"")
A31: Close Rate (closes ÷ showed) | B31: =IFERROR(B22/B21,"") | C31: =IFERROR(C22/C21,"") | D31: =IFERROR(D22/D21,"") | E31: =IFERROR(E22/E21,"") | F31: =IFERROR(F22/F21,"")
A32: DMs per Call Booked | B32: =IFERROR(B15/B20,"") | C32: =IFERROR(C15/C20,"") | D32: =IFERROR(D15/D20,"") | E32: =IFERROR(E15/E20,"") | F32: =IFERROR(F15/F20,"")
A33: Cash per Call Booked | B33: =IFERROR(B23/B20,"") | C33: =IFERROR(C23/C20,"") | D33: =IFERROR(D23/D20,"") | E33: =IFERROR(E23/E20,"") | F33: =IFERROR(F23/F20,"")
A34: Cash per 100 DMs Sent | B34: =IFERROR(B23/B15*100,"") | C34: =IFERROR(C23/C15*100,"") | D34: =IFERROR(D23/D15*100,"") | E34: =IFERROR(E23/E15*100,"") | F34: =IFERROR(F23/F15*100,"")
A36: DAILY STANDARDS — are you holding the line? | G36: Target
A37: Avg Reels / day | B37: =IFERROR(B11/B10,"") | C37: =IFERROR(C11/C10,"") | D37: =IFERROR(D11/D10,"") | E37: =IFERROR(E11/E10,"") | F37: =IFERROR(F11/F10,"") | G37: =Setup!$C$12
A38: Avg Stories / day | B38: =IFERROR(B12/B10,"") | C38: =IFERROR(C12/C10,"") | D38: =IFERROR(D12/D10,"") | E38: =IFERROR(E12/E10,"") | F38: =IFERROR(F12/F10,"") | G38: =Setup!$C$13
A39: Avg Opener DMs / day | B39: =IFERROR(B13/B10,"") | C39: =IFERROR(C13/C10,"") | D39: =IFERROR(D13/D10,"") | E39: =IFERROR(E13/E10,"") | F39: =IFERROR(F13/F10,"") | G39: =Setup!$C$14
A40: Avg Follow-Up DMs / day | B40: =IFERROR(B14/B10,"") | C40: =IFERROR(C14/C10,"") | D40: =IFERROR(D14/D10,"") | E40: =IFERROR(E14/E10,"") | F40: =IFERROR(F14/F10,"") | G40: =Setup!$C$15
A41: Perfect Days (all 4 standards hit) | B41: =COUNTIFS('Daily Log'!$A$4:$A$369,">="&B$6,'Daily Log'!$A$4:$A$369,"<="&B$7,'Daily Log'!$O$4:$O$369,4) | C41: =COUNTIFS('Daily Log'!$A$4:$A$369,">="&C$6,'Daily Log'!$A$4:$A$369,"<="&C$7,'Daily Log'!$O$4:$O$369,4) | D41: =COUNTIFS('Daily Log'!$A$4:$A$369,">="&D$6,'Daily Log'!$A$4:$A$369,"<="&D$7,'Daily Log'!$O$4:$O$369,4) | E41: =COUNTIFS('Daily Log'!$A$4:$A$369,">="&E$6,'Daily Log'!$A$4:$A$369,"<="&E$7,'Daily Log'!$O$4:$O$369,4) | F41: =COUNTIFS('Daily Log'!$A$4:$A$369,">="&F$6,'Daily Log'!$A$4:$A$369,"<="&F$7,'Daily Log'!$O$4:$O$369,4)
A42: Standards Hit Rate | B42: =IFERROR(B41/B10,"") | C42: =IFERROR(C41/C10,"") | D42: =IFERROR(D41/D10,"") | E42: =IFERROR(E41/E10,"") | F42: =IFERROR(F41/F10,"")
A44: TRENDS — last 13 weeks

Sheet Instagram Tracker
A1: INSTAGRAM TRACKER
A2: Weekly numbers off your Professional Dashboard, plus a monthly screenshot so your coach can audit the page.
A4: MONTHLY PROFILE CHECK — first Sunday of the month
A5: 1. Screenshot your profile — bio, follower count and the top of your grid.
A6: 2. Screenshot Professional Dashboard → Insights (last 30 days).
A7: 3. Click the box below, then Insert → Image → Image in cell, and upload.
A9: PROFILE SCREENSHOT | G9: INSIGHTS SCREENSHOT
A10: drop image here | G10: drop image here
A18: WEEKLY NUMBERS — log every Sunday night
A19: Week Starting | B19: Followers (end of week) | C19: Growth (+/-) | D19: Growth % | E19: Accounts Reached | F19: Interactions | G19: Profile Visits | H19: New Followers | I19: Link Clicks | J19: Posts (auto) | K19: Stories (auto) | L19: Reach per Post | M19: New Followers per 1k Reached | N19: Notes
A20: =Setup!$C$9 | B20: 3180 | E20: 9800 | F20: 480 | G20: 310 | H20: 78 | I20: 22 | J20: =IF($A20>TODAY(),"",SUMIFS('Daily Log'!$C$4:$C$369,'Daily Log'!$A$4:$A$369,">="&$A20,'Daily Log'!$A$4:$A$369,"<="&$A20+6)) | K20: =IF($A20>TODAY(),"",SUMIFS('Daily Log'!$D$4:$D$369,'Daily Log'!$A$4:$A$369,">="&$A20,'Daily Log'!$A$4:$A$369,"<="&$A20+6)) | L20: =IFERROR(E20/J20,"") | M20: =IFERROR(H20/E20*1000,"")
A21: =A20+7 | B21: 3268 | C21: =IF(OR(B21="",B20=""),"",B21-B20) | D21: =IF(OR(B21="",B20=""),"",IFERROR((B21-B20)/B20,"")) | E21: 12400 | F21: 620 | G21: 395 | H21: 95 | I21: 31 | J21: =IF($A21>TODAY(),"",SUMIFS('Daily Log'!$C$4:$C$369,'Daily Log'!$A$4:$A$369,">="&$A21,'Daily Log'!$A$4:$A$369,"<="&$A21+6)) | K21: =IF($A21>TODAY(),"",SUMIFS('Daily Log'!$D$4:$D$369,'Daily Log'!$A$4:$A$369,">="&$A21,'Daily Log'!$A$4:$A$369,"<="&$A21+6)) | L21: =IFERROR(E21/J21,"") | M21: =IFERROR(H21/E21*1000,"")
A22: =A21+7 | B22: 3351 | C22: =IF(OR(B22="",B21=""),"",B22-B21) | D22: =IF(OR(B22="",B21=""),"",IFERROR((B22-B21)/B21,"")) | E22: 11100 | F22: 540 | G22: 350 | H22: 88 | I22: 26 | J22: =IF($A22>TODAY(),"",SUMIFS('Daily Log'!$C$4:$C$369,'Daily Log'!$A$4:$A$369,">="&$A22,'Daily Log'!$A$4:$A$369,"<="&$A22+6)) | K22: =IF($A22>TODAY(),"",SUMIFS('Daily Log'!$D$4:$D$369,'Daily Log'!$A$4:$A$369,">="&$A22,'Daily Log'!$A$4:$A$369,"<="&$A22+6)) | L22: =IFERROR(E22/J22,"") | M22: =IFERROR(H22/E22*1000,"")
A23: =A22+7 | B23: 3452 | C23: =IF(OR(B23="",B22=""),"",B23-B22) | D23: =IF(OR(B23="",B22=""),"",IFERROR((B23-B22)/B22,"")) | E23: 14600 | F23: 710 | G23: 430 | H23: 112 | I23: 38 | J23: =IF($A23>TODAY(),"",SUMIFS('Daily Log'!$C$4:$C$369,'Daily Log'!$A$4:$A$369,">="&$A23,'Daily Log'!$A$4:$A$369,"<="&$A23+6)) | K23: =IF($A23>TODAY(),"",SUMIFS('Daily Log'!$D$4:$D$369,'Daily Log'!$A$4:$A$369,">="&$A23,'Daily Log'!$A$4:$A$369,"<="&$A23+6)) | L23: =IFERROR(E23/J23,"") | M23: =IFERROR(H23/E23*1000,"")
A24: =A23+7 | B24: 3530 | C24: =IF(OR(B24="",B23=""),"",B24-B23) | D24: =IF(OR(B24="",B23=""),"",IFERROR((B24-B23)/B23,"")) | E24: 10250 | F24: 505 | G24: 322 | H24: 81 | I24: 24 | J24: =IF($A24>TODAY(),"",SUMIFS('Daily Log'!$C$4:$C$369,'Daily Log'!$A$4:$A$369,">="&$A24,'Daily Log'!$A$4:$A$369,"<="&$A24+6)) | K24: =IF($A24>TODAY(),"",SUMIFS('Daily Log'!$D$4:$D$369,'Daily Log'!$A$4:$A$369,">="&$A24,'Daily Log'!$A$4:$A$369,"<="&$A24+6)) | L24: =IFERROR(E24/J24,"") | M24: =IFERROR(H24/E24*1000,"") | N24: Posted less — reach dropped with it
A25: =A24+7 | B25: 3641 | C25: =IF(OR(B25="",B24=""),"",B25-B24) | D25: =IF(OR(B25="",B24=""),"",IFERROR((B25-B24)/B24,"")) | E25: 15800 | F25: 780 | G25: 468 | H25: 124 | I25: 41 | J25: =IF($A25>TODAY(),"",SUMIFS('Daily Log'!$C$4:$C$369,'Daily Log'!$A$4:$A$369,">="&$A25,'Daily Log'!$A$4:$A$369,"<="&$A25+6)) | K25: =IF($A25>TODAY(),"",SUMIFS('Daily Log'!$D$4:$D$369,'Daily Log'!$A$4:$A$369,">="&$A25,'Daily Log'!$A$4:$A$369,"<="&$A25+6)) | L25: =IFERROR(E25/J25,"") | M25: =IFERROR(H25/E25*1000,"")
A26: =A25+7 | C26: =IF(OR(B26="",B25=""),"",B26-B25) | D26: =IF(OR(B26="",B25=""),"",IFERROR((B26-B25)/B25,"")) | J26: =IF($A26>TODAY(),"",SUMIFS('Daily Log'!$C$4:$C$369,'Daily Log'!$A$4:$A$369,">="&$A26,'Daily Log'!$A$4:$A$369,"<="&$A26+6)) | K26: =IF($A26>TODAY(),"",SUMIFS('Daily Log'!$D$4:$D$369,'Daily Log'!$A$4:$A$369,">="&$A26,'Daily Log'!$A$4:$A$369,"<="&$A26+6)) | L26: =IFERROR(E26/J26,"") | M26: =IFERROR(H26/E26*1000,"")
A27: =A26+7 | C27: =IF(OR(B27="",B26=""),"",B27-B26) | D27: =IF(OR(B27="",B26=""),"",IFERROR((B27-B26)/B26,"")) | J27: =IF($A27>TODAY(),"",SUMIFS('Daily Log'!$C$4:$C$369,'Daily Log'!$A$4:$A$369,">="&$A27,'Daily Log'!$A$4:$A$369,"<="&$A27+6)) | K27: =IF($A27>TODAY(),"",SUMIFS('Daily Log'!$D$4:$D$369,'Daily Log'!$A$4:$A$369,">="&$A27,'Daily Log'!$A$4:$A$369,"<="&$A27+6)) | L27: =IFERROR(E27/J27,"") | M27: =IFERROR(H27/E27*1000,"")
A28: =A27+7 | C28: =IF(OR(B28="",B27=""),"",B28-B27) | D28: =IF(OR(B28="",B27=""),"",IFERROR((B28-B27)/B27,"")) | J28: =IF($A28>TODAY(),"",SUMIFS('Daily Log'!$C$4:$C$369,'Daily Log'!$A$4:$A$369,">="&$A28,'Daily Log'!$A$4:$A$369,"<="&$A28+6)) | K28: =IF($A28>TODAY(),"",SUMIFS('Daily Log'!$D$4:$D$369,'Daily Log'!$A$4:$A$369,">="&$A28,'Daily Log'!$A$4:$A$369,"<="&$A28+6)) | L28: =IFERROR(E28/J28,"") | M28: =IFERROR(H28/E28*1000,"")
A29: =A28+7 | C29: =IF(OR(B29="",B28=""),"",B29-B28) | D29: =IF(OR(B29="",B28=""),"",IFERROR((B29-B28)/B28,"")) | J29: =IF($A29>TODAY(),"",SUMIFS('Daily Log'!$C$4:$C$369,'Daily Log'!$A$4:$A$369,">="&$A29,'Daily Log'!$A$4:$A$369,"<="&$A29+6)) | K29: =IF($A29>TODAY(),"",SUMIFS('Daily Log'!$D$4:$D$369,'Daily Log'!$A$4:$A$369,">="&$A29,'Daily Log'!$A$4:$A$369,"<="&$A29+6)) | L29: =IFERROR(E29/J29,"") | M29: =IFERROR(H29/E29*1000,"")
A30: =A29+7 | C30: =IF(OR(B30="",B29=""),"",B30-B29) | D30: =IF(OR(B30="",B29=""),"",IFERROR((B30-B29)/B29,"")) | J30: =IF($A30>TODAY(),"",SUMIFS('Daily Log'!$C$4:$C$369,'Daily Log'!$A$4:$A$369,">="&$A30,'Daily Log'!$A$4:$A$369,"<="&$A30+6)) | K30: =IF($A30>TODAY(),"",SUMIFS('Daily Log'!$D$4:$D$369,'Daily Log'!$A$4:$A$369,">="&$A30,'Daily Log'!$A$4:$A$369,"<="&$A30+6)) | L30: =IFERROR(E30/J30,"") | M30: =IFERROR(H30/E30*1000,"")
A31: =A30+7 | C31: =IF(OR(B31="",B30=""),"",B31-B30) | D31: =IF(OR(B31="",B30=""),"",IFERROR((B31-B30)/B30,"")) | J31: =IF($A31>TODAY(),"",SUMIFS('Daily Log'!$C$4:$C$369,'Daily Log'!$A$4:$A$369,">="&$A31,'Daily Log'!$A$4:$A$369,"<="&$A31+6)) | K31: =IF($A31>TODAY(),"",SUMIFS('Daily Log'!$D$4:$D$369,'Daily Log'!$A$4:$A$369,">="&$A31,'Daily Log'!$A$4:$A$369,"<="&$A31+6)) | L31: =IFERROR(E31/J31,"") | M31: =IFERROR(H31/E31*1000,"")
A32: =A31+7 | C32: =IF(OR(B32="",B31=""),"",B32-B31) | D32: =IF(OR(B32="",B31=""),"",IFERROR((B32-B31)/B31,"")) | J32: =IF($A32>TODAY(),"",SUMIFS('Daily Log'!$C$4:$C$369,'Daily Log'!$A$4:$A$369,">="&$A32,'Daily Log'!$A$4:$A$369,"<="&$A32+6)) | K32: =IF($A32>TODAY(),"",SUMIFS('Daily Log'!$D$4:$D$369,'Daily Log'!$A$4:$A$369,">="&$A32,'Daily Log'!$A$4:$A$369,"<="&$A32+6)) | L32: =IFERROR(E32/J32,"") | M32: =IFERROR(H32/E32*1000,"")
A33: =A32+7 | C33: =IF(OR(B33="",B32=""),"",B33-B32) | D33: =IF(OR(B33="",B32=""),"",IFERROR((B33-B32)/B32,"")) | J33: =IF($A33>TODAY(),"",SUMIFS('Daily Log'!$C$4:$C$369,'Daily Log'!$A$4:$A$369,">="&$A33,'Daily Log'!$A$4:$A$369,"<="&$A33+6)) | K33: =IF($A33>TODAY(),"",SUMIFS('Daily Log'!$D$4:$D$369,'Daily Log'!$A$4:$A$369,">="&$A33,'Daily Log'!$A$4:$A$369,"<="&$A33+6)) | L33: =IFERROR(E33/J33,"") | M33: =IFERROR(H33/E33*1000,"")
A34: =A33+7 | C34: =IF(OR(B34="",B33=""),"",B34-B33) | D34: =IF(OR(B34="",B33=""),"",IFERROR((B34-B33)/B33,"")) | J34: =IF($A34>TODAY(),"",SUMIFS('Daily Log'!$C$4:$C$369,'Daily Log'!$A$4:$A$369,">="&$A34,'Daily Log'!$A$4:$A$369,"<="&$A34+6)) | K34: =IF($A34>TODAY(),"",SUMIFS('Daily Log'!$D$4:$D$369,'Daily Log'!$A$4:$A$369,">="&$A34,'Daily Log'!$A$4:$A$369,"<="&$A34+6)) | L34: =IFERROR(E34/J34,"") | M34: =IFERROR(H34/E34*1000,"")
A35: =A34+7 | C35: =IF(OR(B35="",B34=""),"",B35-B34) | D35: =IF(OR(B35="",B34=""),"",IFERROR((B35-B34)/B34,"")) | J35: =IF($A35>TODAY(),"",SUMIFS('Daily Log'!$C$4:$C$369,'Daily Log'!$A$4:$A$369,">="&$A35,'Daily Log'!$A$4:$A$369,"<="&$A35+6)) | K35: =IF($A35>TODAY(),"",SUMIFS('Daily Log'!$D$4:$D$369,'Daily Log'!$A$4:$A$369,">="&$A35,'Daily Log'!$A$4:$A$369,"<="&$A35+6)) | L35: =IFERROR(E35/J35,"") | M35: =IFERROR(H35/E35*1000,"")
A36: =A35+7 | C36: =IF(OR(B36="",B35=""),"",B36-B35) | D36: =IF(OR(B36="",B35=""),"",IFERROR((B36-B35)/B35,"")) | J36: =IF($A36>TODAY(),"",SUMIFS('Daily Log'!$C$4:$C$369,'Daily Log'!$A$4:$A$369,">="&$A36,'Daily Log'!$A$4:$A$369,"<="&$A36+6)) | K36: =IF($A36>TODAY(),"",SUMIFS('Daily Log'!$D$4:$D$369,'Daily Log'!$A$4:$A$369,">="&$A36,'Daily Log'!$A$4:$A$369,"<="&$A36+6)) | L36: =IFERROR(E36/J36,"") | M36: =IFERROR(H36/E36*1000,"")
A37: =A36+7 | C37: =IF(OR(B37="",B36=""),"",B37-B36) | D37: =IF(OR(B37="",B36=""),"",IFERROR((B37-B36)/B36,"")) | J37: =IF($A37>TODAY(),"",SUMIFS('Daily Log'!$C$4:$C$369,'Daily Log'!$A$4:$A$369,">="&$A37,'Daily Log'!$A$4:$A$369,"<="&$A37+6)) | K37: =IF($A37>TODAY(),"",SUMIFS('Daily Log'!$D$4:$D$369,'Daily Log'!$A$4:$A$369,">="&$A37,'Daily Log'!$A$4:$A$369,"<="&$A37+6)) | L37: =IFERROR(E37/J37,"") | M37: =IFERROR(H37/E37*1000,"")
... A72: =A71+7 | C72: =IF(OR(B72="",B71=""),"",B72-B71) | D72: =IF(OR(B72="",B71=""),"",IFERROR((B72-B71)/B71,"")) | J72: =IF($A72>TODAY(),"",SUMIFS('Daily Log'!$C$4:$C$369,'Daily Log'!$A$4:$A$369,">="&$A72,'Daily Log'!$A$4:$A$369,"<="&$A72+6)) | K72: =IF($A72>TODAY(),"",SUMIFS('Daily Log'!$D$4:$D$369,'Daily Log'!$A$4:$A$369,">="&$A72,'Daily Log'!$A$4:$A$369,"<="&$A72+6)) | L72: =IFERROR(E72/J72,"") | M72: =IFERROR(H72/E72*1000,"")

Sheet Weekly Rollup
A1: WEEKLY ROLLUP — your last 13 weeks
A2: All automatic. This is what the dashboard charts read from. Nothing to fill in here.
A3: Week Starting | B3: Week | C3: Days Logged | D3: Reels / Posts | E3: Stories | F3: Opener DMs | G3: Follow-Up DMs | H3: Total DMs Sent | I3: Replies | J3: Calls Pitched | K3: Calls Booked | L3: Calls Showed | M3: Closes | N3: Cash Collected | O3: Revenue | P3: Reply Rate | Q3: Book Rate | R3: Close Rate
A4: =TODAY()-WEEKDAY(TODAY(),2)+1-84 | B4: =IF(A4="","",TEXT(A4,"d mmm")) | C4: =IF($A4<Setup!$C$9,"",SUMIFS('Daily Log'!$Q$4:$Q$369,'Daily Log'!$A$4:$A$369,">="&$A4,'Daily Log'!$A$4:$A$369,"<="&$A4+6)) | D4: =IF($A4<Setup!$C$9,"",SUMIFS('Daily Log'!$C$4:$C$369,'Daily Log'!$A$4:$A$369,">="&$A4,'Daily Log'!$A$4:$A$369,"<="&$A4+6)) | E4: =IF($A4<Setup!$C$9,"",SUMIFS('Daily Log'!$D$4:$D$369,'Daily Log'!$A$4:$A$369,">="&$A4,'Daily Log'!$A$4:$A$369,"<="&$A4+6)) | F4: =IF($A4<Setup!$C$9,"",SUMIFS('Daily Log'!$E$4:$E$369,'Daily Log'!$A$4:$A$369,">="&$A4,'Daily Log'!$A$4:$A$369,"<="&$A4+6)) | G4: =IF($A4<Setup!$C$9,"",SUMIFS('Daily Log'!$F$4:$F$369,'Daily Log'!$A$4:$A$369,">="&$A4,'Daily Log'!$A$4:$A$369,"<="&$A4+6)) | H4: =IF($A4<Setup!$C$9,"",IFERROR(F4+G4,"")) | I4: =IF($A4<Setup!$C$9,"",SUMIFS('Daily Log'!$G$4:$G$369,'Daily Log'!$A$4:$A$369,">="&$A4,'Daily Log'!$A$4:$A$369,"<="&$A4+6)) | J4: =IF($A4<Setup!$C$9,"",SUMIFS('Daily Log'!$H$4:$H$369,'Daily Log'!$A$4:$A$369,">="&$A4,'Daily Log'!$A$4:$A$369,"<="&$A4+6)) | K4: =IF($A4<Setup!$C$9,"",SUMIFS('Daily Log'!$I$4:$I$369,'Daily Log'!$A$4:$A$369,">="&$A4,'Daily Log'!$A$4:$A$369,"<="&$A4+6)) | L4: =IF($A4<Setup!$C$9,"",SUMIFS('Daily Log'!$J$4:$J$369,'Daily Log'!$A$4:$A$369,">="&$A4,'Daily Log'!$A$4:$A$369,"<="&$A4+6)) | M4: =IF($A4<Setup!$C$9,"",SUMIFS('Daily Log'!$K$4:$K$369,'Daily Log'!$A$4:$A$369,">="&$A4,'Daily Log'!$A$4:$A$369,"<="&$A4+6)) | N4: =IF($A4<Setup!$C$9,"",SUMIFS('Daily Log'!$L$4:$L$369,'Daily Log'!$A$4:$A$369,">="&$A4,'Daily Log'!$A$4:$A$369,"<="&$A4+6)) | O4: =IF($A4<Setup!$C$9,"",SUMIFS('Daily Log'!$M$4:$M$369,'Daily Log'!$A$4:$A$369,">="&$A4,'Daily Log'!$A$4:$A$369,"<="&$A4+6)) | P4: =IFERROR(I4/H4,"") | Q4: =IFERROR(K4/J4,"") | R4: =IFERROR(M4/L4,"")
A5: =A4+7 | B5: =IF(A5="","",TEXT(A5,"d mmm")) | C5: =IF($A5<Setup!$C$9,"",SUMIFS('Daily Log'!$Q$4:$Q$369,'Daily Log'!$A$4:$A$369,">="&$A5,'Daily Log'!$A$4:$A$369,"<="&$A5+6)) | D5: =IF($A5<Setup!$C$9,"",SUMIFS('Daily Log'!$C$4:$C$369,'Daily Log'!$A$4:$A$369,">="&$A5,'Daily Log'!$A$4:$A$369,"<="&$A5+6)) | E5: =IF($A5<Setup!$C$9,"",SUMIFS('Daily Log'!$D$4:$D$369,'Daily Log'!$A$4:$A$369,">="&$A5,'Daily Log'!$A$4:$A$369,"<="&$A5+6)) | F5: =IF($A5<Setup!$C$9,"",SUMIFS('Daily Log'!$E$4:$E$369,'Daily Log'!$A$4:$A$369,">="&$A5,'Daily Log'!$A$4:$A$369,"<="&$A5+6)) | G5: =IF($A5<Setup!$C$9,"",SUMIFS('Daily Log'!$F$4:$F$369,'Daily Log'!$A$4:$A$369,">="&$A5,'Daily Log'!$A$4:$A$369,"<="&$A5+6)) | H5: =IF($A5<Setup!$C$9,"",IFERROR(F5+G5,"")) | I5: =IF($A5<Setup!$C$9,"",SUMIFS('Daily Log'!$G$4:$G$369,'Daily Log'!$A$4:$A$369,">="&$A5,'Daily Log'!$A$4:$A$369,"<="&$A5+6)) | J5: =IF($A5<Setup!$C$9,"",SUMIFS('Daily Log'!$H$4:$H$369,'Daily Log'!$A$4:$A$369,">="&$A5,'Daily Log'!$A$4:$A$369,"<="&$A5+6)) | K5: =IF($A5<Setup!$C$9,"",SUMIFS('Daily Log'!$I$4:$I$369,'Daily Log'!$A$4:$A$369,">="&$A5,'Daily Log'!$A$4:$A$369,"<="&$A5+6)) | L5: =IF($A5<Setup!$C$9,"",SUMIFS('Daily Log'!$J$4:$J$369,'Daily Log'!$A$4:$A$369,">="&$A5,'Daily Log'!$A$4:$A$369,"<="&$A5+6)) | M5: =IF($A5<Setup!$C$9,"",SUMIFS('Daily Log'!$K$4:$K$369,'Daily Log'!$A$4:$A$369,">="&$A5,'Daily Log'!$A$4:$A$369,"<="&$A5+6)) | N5: =IF($A5<Setup!$C$9,"",SUMIFS('Daily Log'!$L$4:$L$369,'Daily Log'!$A$4:$A$369,">="&$A5,'Daily Log'!$A$4:$A$369,"<="&$A5+6)) | O5: =IF($A5<Setup!$C$9,"",SUMIFS('Daily Log'!$M$4:$M$369,'Daily Log'!$A$4:$A$369,">="&$A5,'Daily Log'!$A$4:$A$369,"<="&$A5+6)) | P5: =IFERROR(I5/H5,"") | Q5: =IFERROR(K5/J5,"") | R5: =IFERROR(M5/L5,"")
A6: =A5+7 | B6: =IF(A6="","",TEXT(A6,"d mmm")) | C6: =IF($A6<Setup!$C$9,"",SUMIFS('Daily Log'!$Q$4:$Q$369,'Daily Log'!$A$4:$A$369,">="&$A6,'Daily Log'!$A$4:$A$369,"<="&$A6+6)) | D6: =IF($A6<Setup!$C$9,"",SUMIFS('Daily Log'!$C$4:$C$369,'Daily Log'!$A$4:$A$369,">="&$A6,'Daily Log'!$A$4:$A$369,"<="&$A6+6)) | E6: =IF($A6<Setup!$C$9,"",SUMIFS('Daily Log'!$D$4:$D$369,'Daily Log'!$A$4:$A$369,">="&$A6,'Daily Log'!$A$4:$A$369,"<="&$A6+6)) | F6: =IF($A6<Setup!$C$9,"",SUMIFS('Daily Log'!$E$4:$E$369,'Daily Log'!$A$4:$A$369,">="&$A6,'Daily Log'!$A$4:$A$369,"<="&$A6+6)) | G6: =IF($A6<Setup!$C$9,"",SUMIFS('Daily Log'!$F$4:$F$369,'Daily Log'!$A$4:$A$369,">="&$A6,'Daily Log'!$A$4:$A$369,"<="&$A6+6)) | H6: =IF($A6<Setup!$C$9,"",IFERROR(F6+G6,"")) | I6: =IF($A6<Setup!$C$9,"",SUMIFS('Daily Log'!$G$4:$G$369,'Daily Log'!$A$4:$A$369,">="&$A6,'Daily Log'!$A$4:$A$369,"<="&$A6+6)) | J6: =IF($A6<Setup!$C$9,"",SUMIFS('Daily Log'!$H$4:$H$369,'Daily Log'!$A$4:$A$369,">="&$A6,'Daily Log'!$A$4:$A$369,"<="&$A6+6)) | K6: =IF($A6<Setup!$C$9,"",SUMIFS('Daily Log'!$I$4:$I$369,'Daily Log'!$A$4:$A$369,">="&$A6,'Daily Log'!$A$4:$A$369,"<="&$A6+6)) | L6: =IF($A6<Setup!$C$9,"",SUMIFS('Daily Log'!$J$4:$J$369,'Daily Log'!$A$4:$A$369,">="&$A6,'Daily Log'!$A$4:$A$369,"<="&$A6+6)) | M6: =IF($A6<Setup!$C$9,"",SUMIFS('Daily Log'!$K$4:$K$369,'Daily Log'!$A$4:$A$369,">="&$A6,'Daily Log'!$A$4:$A$369,"<="&$A6+6)) | N6: =IF($A6<Setup!$C$9,"",SUMIFS('Daily Log'!$L$4:$L$369,'Daily Log'!$A$4:$A$369,">="&$A6,'Daily Log'!$A$4:$A$369,"<="&$A6+6)) | O6: =IF($A6<Setup!$C$9,"",SUMIFS('Daily Log'!$M$4:$M$369,'Daily Log'!$A$4:$A$369,">="&$A6,'Daily Log'!$A$4:$A$369,"<="&$A6+6)) | P6: =IFERROR(I6/H6,"") | Q6: =IFERROR(K6/J6,"") | R6: =IFERROR(M6/L6,"")
A7: =A6+7 | B7: =IF(A7="","",TEXT(A7,"d mmm")) | C7: =IF($A7<Setup!$C$9,"",SUMIFS('Daily Log'!$Q$4:$Q$369,'Daily Log'!$A$4:$A$369,">="&$A7,'Daily Log'!$A$4:$A$369,"<="&$A7+6)) | D7: =IF($A7<Setup!$C$9,"",SUMIFS('Daily Log'!$C$4:$C$369,'Daily Log'!$A$4:$A$369,">="&$A7,'Daily Log'!$A$4:$A$369,"<="&$A7+6)) | E7: =IF($A7<Setup!$C$9,"",SUMIFS('Daily Log'!$D$4:$D$369,'Daily Log'!$A$4:$A$369,">="&$A7,'Daily Log'!$A$4:$A$369,"<="&$A7+6)) | F7: =IF($A7<Setup!$C$9,"",SUMIFS('Daily Log'!$E$4:$E$369,'Daily Log'!$A$4:$A$369,">="&$A7,'Daily Log'!$A$4:$A$369,"<="&$A7+6)) | G7: =IF($A7<Setup!$C$9,"",SUMIFS('Daily Log'!$F$4:$F$369,'Daily Log'!$A$4:$A$369,">="&$A7,'Daily Log'!$A$4:$A$369,"<="&$A7+6)) | H7: =IF($A7<Setup!$C$9,"",IFERROR(F7+G7,"")) | I7: =IF($A7<Setup!$C$9,"",SUMIFS('Daily Log'!$G$4:$G$369,'Daily Log'!$A$4:$A$369,">="&$A7,'Daily Log'!$A$4:$A$369,"<="&$A7+6)) | J7: =IF($A7<Setup!$C$9,"",SUMIFS('Daily Log'!$H$4:$H$369,'Daily Log'!$A$4:$A$369,">="&$A7,'Daily Log'!$A$4:$A$369,"<="&$A7+6)) | K7: =IF($A7<Setup!$C$9,"",SUMIFS('Daily Log'!$I$4:$I$369,'Daily Log'!$A$4:$A$369,">="&$A7,'Daily Log'!$A$4:$A$369,"<="&$A7+6)) | L7: =IF($A7<Setup!$C$9,"",SUMIFS('Daily Log'!$J$4:$J$369,'Daily Log'!$A$4:$A$369,">="&$A7,'Daily Log'!$A$4:$A$369,"<="&$A7+6)) | M7: =IF($A7<Setup!$C$9,"",SUMIFS('Daily Log'!$K$4:$K$369,'Daily Log'!$A$4:$A$369,">="&$A7,'Daily Log'!$A$4:$A$369,"<="&$A7+6)) | N7: =IF($A7<Setup!$C$9,"",SUMIFS('Daily Log'!$L$4:$L$369,'Daily Log'!$A$4:$A$369,">="&$A7,'Daily Log'!$A$4:$A$369,"<="&$A7+6)) | O7: =IF($A7<Setup!$C$9,"",SUMIFS('Daily Log'!$M$4:$M$369,'Daily Log'!$A$4:$A$369,">="&$A7,'Daily Log'!$A$4:$A$369,"<="&$A7+6)) | P7: =IFERROR(I7/H7,"") | Q7: =IFERROR(K7/J7,"") | R7: =IFERROR(M7/L7,"")
A8: =A7+7 | B8: =IF(A8="","",TEXT(A8,"d mmm")) | C8: =IF($A8<Setup!$C$9,"",SUMIFS('Daily Log'!$Q$4:$Q$369,'Daily Log'!$A$4:$A$369,">="&$A8,'Daily Log'!$A$4:$A$369,"<="&$A8+6)) | D8: =IF($A8<Setup!$C$9,"",SUMIFS('Daily Log'!$C$4:$C$369,'Daily Log'!$A$4:$A$369,">="&$A8,'Daily Log'!$A$4:$A$369,"<="&$A8+6)) | E8: =IF($A8<Setup!$C$9,"",SUMIFS('Daily Log'!$D$4:$D$369,'Daily Log'!$A$4:$A$369,">="&$A8,'Daily Log'!$A$4:$A$369,"<="&$A8+6)) | F8: =IF($A8<Setup!$C$9,"",SUMIFS('Daily Log'!$E$4:$E$369,'Daily Log'!$A$4:$A$369,">="&$A8,'Daily Log'!$A$4:$A$369,"<="&$A8+6)) | G8: =IF($A8<Setup!$C$9,"",SUMIFS('Daily Log'!$F$4:$F$369,'Daily Log'!$A$4:$A$369,">="&$A8,'Daily Log'!$A$4:$A$369,"<="&$A8+6)) | H8: =IF($A8<Setup!$C$9,"",IFERROR(F8+G8,"")) | I8: =IF($A8<Setup!$C$9,"",SUMIFS('Daily Log'!$G$4:$G$369,'Daily Log'!$A$4:$A$369,">="&$A8,'Daily Log'!$A$4:$A$369,"<="&$A8+6)) | J8: =IF($A8<Setup!$C$9,"",SUMIFS('Daily Log'!$H$4:$H$369,'Daily Log'!$A$4:$A$369,">="&$A8,'Daily Log'!$A$4:$A$369,"<="&$A8+6)) | K8: =IF($A8<Setup!$C$9,"",SUMIFS('Daily Log'!$I$4:$I$369,'Daily Log'!$A$4:$A$369,">="&$A8,'Daily Log'!$A$4:$A$369,"<="&$A8+6)) | L8: =IF($A8<Setup!$C$9,"",SUMIFS('Daily Log'!$J$4:$J$369,'Daily Log'!$A$4:$A$369,">="&$A8,'Daily Log'!$A$4:$A$369,"<="&$A8+6)) | M8: =IF($A8<Setup!$C$9,"",SUMIFS('Daily Log'!$K$4:$K$369,'Daily Log'!$A$4:$A$369,">="&$A8,'Daily Log'!$A$4:$A$369,"<="&$A8+6)) | N8: =IF($A8<Setup!$C$9,"",SUMIFS('Daily Log'!$L$4:$L$369,'Daily Log'!$A$4:$A$369,">="&$A8,'Daily Log'!$A$4:$A$369,"<="&$A8+6)) | O8: =IF($A8<Setup!$C$9,"",SUMIFS('Daily Log'!$M$4:$M$369,'Daily Log'!$A$4:$A$369,">="&$A8,'Daily Log'!$A$4:$A$369,"<="&$A8+6)) | P8: =IFERROR(I8/H8,"") | Q8: =IFERROR(K8/J8,"") | R8: =IFERROR(M8/L8,"")
A9: =A8+7 | B9: =IF(A9="","",TEXT(A9,"d mmm")) | C9: =IF($A9<Setup!$C$9,"",SUMIFS('Daily Log'!$Q$4:$Q$369,'Daily Log'!$A$4:$A$369,">="&$A9,'Daily Log'!$A$4:$A$369,"<="&$A9+6)) | D9: =IF($A9<Setup!$C$9,"",SUMIFS('Daily Log'!$C$4:$C$369,'Daily Log'!$A$4:$A$369,">="&$A9,'Daily Log'!$A$4:$A$369,"<="&$A9+6)) | E9: =IF($A9<Setup!$C$9,"",SUMIFS('Daily Log'!$D$4:$D$369,'Daily Log'!$A$4:$A$369,">="&$A9,'Daily Log'!$A$4:$A$369,"<="&$A9+6)) | F9: =IF($A9<Setup!$C$9,"",SUMIFS('Daily Log'!$E$4:$E$369,'Daily Log'!$A$4:$A$369,">="&$A9,'Daily Log'!$A$4:$A$369,"<="&$A9+6)) | G9: =IF($A9<Setup!$C$9,"",SUMIFS('Daily Log'!$F$4:$F$369,'Daily Log'!$A$4:$A$369,">="&$A9,'Daily Log'!$A$4:$A$369,"<="&$A9+6)) | H9: =IF($A9<Setup!$C$9,"",IFERROR(F9+G9,"")) | I9: =IF($A9<Setup!$C$9,"",SUMIFS('Daily Log'!$G$4:$G$369,'Daily Log'!$A$4:$A$369,">="&$A9,'Daily Log'!$A$4:$A$369,"<="&$A9+6)) | J9: =IF($A9<Setup!$C$9,"",SUMIFS('Daily Log'!$H$4:$H$369,'Daily Log'!$A$4:$A$369,">="&$A9,'Daily Log'!$A$4:$A$369,"<="&$A9+6)) | K9: =IF($A9<Setup!$C$9,"",SUMIFS('Daily Log'!$I$4:$I$369,'Daily Log'!$A$4:$A$369,">="&$A9,'Daily Log'!$A$4:$A$369,"<="&$A9+6)) | L9: =IF($A9<Setup!$C$9,"",SUMIFS('Daily Log'!$J$4:$J$369,'Daily Log'!$A$4:$A$369,">="&$A9,'Daily Log'!$A$4:$A$369,"<="&$A9+6)) | M9: =IF($A9<Setup!$C$9,"",SUMIFS('Daily Log'!$K$4:$K$369,'Daily Log'!$A$4:$A$369,">="&$A9,'Daily Log'!$A$4:$A$369,"<="&$A9+6)) | N9: =IF($A9<Setup!$C$9,"",SUMIFS('Daily Log'!$L$4:$L$369,'Daily Log'!$A$4:$A$369,">="&$A9,'Daily Log'!$A$4:$A$369,"<="&$A9+6)) | O9: =IF($A9<Setup!$C$9,"",SUMIFS('Daily Log'!$M$4:$M$369,'Daily Log'!$A$4:$A$369,">="&$A9,'Daily Log'!$A$4:$A$369,"<="&$A9+6)) | P9: =IFERROR(I9/H9,"") | Q9: =IFERROR(K9/J9,"") | R9: =IFERROR(M9/L9,"")
A10: =A9+7 | B10: =IF(A10="","",TEXT(A10,"d mmm")) | C10: =IF($A10<Setup!$C$9,"",SUMIFS('Daily Log'!$Q$4:$Q$369,'Daily Log'!$A$4:$A$369,">="&$A10,'Daily Log'!$A$4:$A$369,"<="&$A10+6)) | D10: =IF($A10<Setup!$C$9,"",SUMIFS('Daily Log'!$C$4:$C$369,'Daily Log'!$A$4:$A$369,">="&$A10,'Daily Log'!$A$4:$A$369,"<="&$A10+6)) | E10: =IF($A10<Setup!$C$9,"",SUMIFS('Daily Log'!$D$4:$D$369,'Daily Log'!$A$4:$A$369,">="&$A10,'Daily Log'!$A$4:$A$369,"<="&$A10+6)) | F10: =IF($A10<Setup!$C$9,"",SUMIFS('Daily Log'!$E$4:$E$369,'Daily Log'!$A$4:$A$369,">="&$A10,'Daily Log'!$A$4:$A$369,"<="&$A10+6)) | G10: =IF($A10<Setup!$C$9,"",SUMIFS('Daily Log'!$F$4:$F$369,'Daily Log'!$A$4:$A$369,">="&$A10,'Daily Log'!$A$4:$A$369,"<="&$A10+6)) | H10: =IF($A10<Setup!$C$9,"",IFERROR(F10+G10,"")) | I10: =IF($A10<Setup!$C$9,"",SUMIFS('Daily Log'!$G$4:$G$369,'Daily Log'!$A$4:$A$369,">="&$A10,'Daily Log'!$A$4:$A$369,"<="&$A10+6)) | J10: =IF($A10<Setup!$C$9,"",SUMIFS('Daily Log'!$H$4:$H$369,'Daily Log'!$A$4:$A$369,">="&$A10,'Daily Log'!$A$4:$A$369,"<="&$A10+6)) | K10: =IF($A10<Setup!$C$9,"",SUMIFS('Daily Log'!$I$4:$I$369,'Daily Log'!$A$4:$A$369,">="&$A10,'Daily Log'!$A$4:$A$369,"<="&$A10+6)) | L10: =IF($A10<Setup!$C$9,"",SUMIFS('Daily Log'!$J$4:$J$369,'Daily Log'!$A$4:$A$369,">="&$A10,'Daily Log'!$A$4:$A$369,"<="&$A10+6)) | M10: =IF($A10<Setup!$C$9,"",SUMIFS('Daily Log'!$K$4:$K$369,'Daily Log'!$A$4:$A$369,">="&$A10,'Daily Log'!$A$4:$A$369,"<="&$A10+6)) | N10: =IF($A10<Setup!$C$9,"",SUMIFS('Daily Log'!$L$4:$L$369,'Daily Log'!$A$4:$A$369,">="&$A10,'Daily Log'!$A$4:$A$369,"<="&$A10+6)) | O10: =IF($A10<Setup!$C$9,"",SUMIFS('Daily Log'!$M$4:$M$369,'Daily Log'!$A$4:$A$369,">="&$A10,'Daily Log'!$A$4:$A$369,"<="&$A10+6)) | P10: =IFERROR(I10/H10,"") | Q10: =IFERROR(K10/J10,"") | R10: =IFERROR(M10/L10,"")
A11: =A10+7 | B11: =IF(A11="","",TEXT(A11,"d mmm")) | C11: =IF($A11<Setup!$C$9,"",SUMIFS('Daily Log'!$Q$4:$Q$369,'Daily Log'!$A$4:$A$369,">="&$A11,'Daily Log'!$A$4:$A$369,"<="&$A11+6)) | D11: =IF($A11<Setup!$C$9,"",SUMIFS('Daily Log'!$C$4:$C$369,'Daily Log'!$A$4:$A$369,">="&$A11,'Daily Log'!$A$4:$A$369,"<="&$A11+6)) | E11: =IF($A11<Setup!$C$9,"",SUMIFS('Daily Log'!$D$4:$D$369,'Daily Log'!$A$4:$A$369,">="&$A11,'Daily Log'!$A$4:$A$369,"<="&$A11+6)) | F11: =IF($A11<Setup!$C$9,"",SUMIFS('Daily Log'!$E$4:$E$369,'Daily Log'!$A$4:$A$369,">="&$A11,'Daily Log'!$A$4:$A$369,"<="&$A11+6)) | G11: =IF($A11<Setup!$C$9,"",SUMIFS('Daily Log'!$F$4:$F$369,'Daily Log'!$A$4:$A$369,">="&$A11,'Daily Log'!$A$4:$A$369,"<="&$A11+6)) | H11: =IF($A11<Setup!$C$9,"",IFERROR(F11+G11,"")) | I11: =IF($A11<Setup!$C$9,"",SUMIFS('Daily Log'!$G$4:$G$369,'Daily Log'!$A$4:$A$369,">="&$A11,'Daily Log'!$A$4:$A$369,"<="&$A11+6)) | J11: =IF($A11<Setup!$C$9,"",SUMIFS('Daily Log'!$H$4:$H$369,'Daily Log'!$A$4:$A$369,">="&$A11,'Daily Log'!$A$4:$A$369,"<="&$A11+6)) | K11: =IF($A11<Setup!$C$9,"",SUMIFS('Daily Log'!$I$4:$I$369,'Daily Log'!$A$4:$A$369,">="&$A11,'Daily Log'!$A$4:$A$369,"<="&$A11+6)) | L11: =IF($A11<Setup!$C$9,"",SUMIFS('Daily Log'!$J$4:$J$369,'Daily Log'!$A$4:$A$369,">="&$A11,'Daily Log'!$A$4:$A$369,"<="&$A11+6)) | M11: =IF($A11<Setup!$C$9,"",SUMIFS('Daily Log'!$K$4:$K$369,'Daily Log'!$A$4:$A$369,">="&$A11,'Daily Log'!$A$4:$A$369,"<="&$A11+6)) | N11: =IF($A11<Setup!$C$9,"",SUMIFS('Daily Log'!$L$4:$L$369,'Daily Log'!$A$4:$A$369,">="&$A11,'Daily Log'!$A$4:$A$369,"<="&$A11+6)) | O11: =IF($A11<Setup!$C$9,"",SUMIFS('Daily Log'!$M$4:$M$369,'Daily Log'!$A$4:$A$369,">="&$A11,'Daily Log'!$A$4:$A$369,"<="&$A11+6)) | P11: =IFERROR(I11/H11,"") | Q11: =IFERROR(K11/J11,"") | R11: =IFERROR(M11/L11,"")
A12: =A11+7 | B12: =IF(A12="","",TEXT(A12,"d mmm")) | C12: =IF($A12<Setup!$C$9,"",SUMIFS('Daily Log'!$Q$4:$Q$369,'Daily Log'!$A$4:$A$369,">="&$A12,'Daily Log'!$A$4:$A$369,"<="&$A12+6)) | D12: =IF($A12<Setup!$C$9,"",SUMIFS('Daily Log'!$C$4:$C$369,'Daily Log'!$A$4:$A$369,">="&$A12,'Daily Log'!$A$4:$A$369,"<="&$A12+6)) | E12: =IF($A12<Setup!$C$9,"",SUMIFS('Daily Log'!$D$4:$D$369,'Daily Log'!$A$4:$A$369,">="&$A12,'Daily Log'!$A$4:$A$369,"<="&$A12+6)) | F12: =IF($A12<Setup!$C$9,"",SUMIFS('Daily Log'!$E$4:$E$369,'Daily Log'!$A$4:$A$369,">="&$A12,'Daily Log'!$A$4:$A$369,"<="&$A12+6)) | G12: =IF($A12<Setup!$C$9,"",SUMIFS('Daily Log'!$F$4:$F$369,'Daily Log'!$A$4:$A$369,">="&$A12,'Daily Log'!$A$4:$A$369,"<="&$A12+6)) | H12: =IF($A12<Setup!$C$9,"",IFERROR(F12+G12,"")) | I12: =IF($A12<Setup!$C$9,"",SUMIFS('Daily Log'!$G$4:$G$369,'Daily Log'!$A$4:$A$369,">="&$A12,'Daily Log'!$A$4:$A$369,"<="&$A12+6)) | J12: =IF($A12<Setup!$C$9,"",SUMIFS('Daily Log'!$H$4:$H$369,'Daily Log'!$A$4:$A$369,">="&$A12,'Daily Log'!$A$4:$A$369,"<="&$A12+6)) | K12: =IF($A12<Setup!$C$9,"",SUMIFS('Daily Log'!$I$4:$I$369,'Daily Log'!$A$4:$A$369,">="&$A12,'Daily Log'!$A$4:$A$369,"<="&$A12+6)) | L12: =IF($A12<Setup!$C$9,"",SUMIFS('Daily Log'!$J$4:$J$369,'Daily Log'!$A$4:$A$369,">="&$A12,'Daily Log'!$A$4:$A$369,"<="&$A12+6)) | M12: =IF($A12<Setup!$C$9,"",SUMIFS('Daily Log'!$K$4:$K$369,'Daily Log'!$A$4:$A$369,">="&$A12,'Daily Log'!$A$4:$A$369,"<="&$A12+6)) | N12: =IF($A12<Setup!$C$9,"",SUMIFS('Daily Log'!$L$4:$L$369,'Daily Log'!$A$4:$A$369,">="&$A12,'Daily Log'!$A$4:$A$369,"<="&$A12+6)) | O12: =IF($A12<Setup!$C$9,"",SUMIFS('Daily Log'!$M$4:$M$369,'Daily Log'!$A$4:$A$369,">="&$A12,'Daily Log'!$A$4:$A$369,"<="&$A12+6)) | P12: =IFERROR(I12/H12,"") | Q12: =IFERROR(K12/J12,"") | R12: =IFERROR(M12/L12,"")
A13: =A12+7 | B13: =IF(A13="","",TEXT(A13,"d mmm")) | C13: =IF($A13<Setup!$C$9,"",SUMIFS('Daily Log'!$Q$4:$Q$369,'Daily Log'!$A$4:$A$369,">="&$A13,'Daily Log'!$A$4:$A$369,"<="&$A13+6)) | D13: =IF($A13<Setup!$C$9,"",SUMIFS('Daily Log'!$C$4:$C$369,'Daily Log'!$A$4:$A$369,">="&$A13,'Daily Log'!$A$4:$A$369,"<="&$A13+6)) | E13: =IF($A13<Setup!$C$9,"",SUMIFS('Daily Log'!$D$4:$D$369,'Daily Log'!$A$4:$A$369,">="&$A13,'Daily Log'!$A$4:$A$369,"<="&$A13+6)) | F13: =IF($A13<Setup!$C$9,"",SUMIFS('Daily Log'!$E$4:$E$369,'Daily Log'!$A$4:$A$369,">="&$A13,'Daily Log'!$A$4:$A$369,"<="&$A13+6)) | G13: =IF($A13<Setup!$C$9,"",SUMIFS('Daily Log'!$F$4:$F$369,'Daily Log'!$A$4:$A$369,">="&$A13,'Daily Log'!$A$4:$A$369,"<="&$A13+6)) | H13: =IF($A13<Setup!$C$9,"",IFERROR(F13+G13,"")) | I13: =IF($A13<Setup!$C$9,"",SUMIFS('Daily Log'!$G$4:$G$369,'Daily Log'!$A$4:$A$369,">="&$A13,'Daily Log'!$A$4:$A$369,"<="&$A13+6)) | J13: =IF($A13<Setup!$C$9,"",SUMIFS('Daily Log'!$H$4:$H$369,'Daily Log'!$A$4:$A$369,">="&$A13,'Daily Log'!$A$4:$A$369,"<="&$A13+6)) | K13: =IF($A13<Setup!$C$9,"",SUMIFS('Daily Log'!$I$4:$I$369,'Daily Log'!$A$4:$A$369,">="&$A13,'Daily Log'!$A$4:$A$369,"<="&$A13+6)) | L13: =IF($A13<Setup!$C$9,"",SUMIFS('Daily Log'!$J$4:$J$369,'Daily Log'!$A$4:$A$369,">="&$A13,'Daily Log'!$A$4:$A$369,"<="&$A13+6)) | M13: =IF($A13<Setup!$C$9,"",SUMIFS('Daily Log'!$K$4:$K$369,'Daily Log'!$A$4:$A$369,">="&$A13,'Daily Log'!$A$4:$A$369,"<="&$A13+6)) | N13: =IF($A13<Setup!$C$9,"",SUMIFS('Daily Log'!$L$4:$L$369,'Daily Log'!$A$4:$A$369,">="&$A13,'Daily Log'!$A$4:$A$369,"<="&$A13+6)) | O13: =IF($A13<Setup!$C$9,"",SUMIFS('Daily Log'!$M$4:$M$369,'Daily Log'!$A$4:$A$369,">="&$A13,'Daily Log'!$A$4:$A$369,"<="&$A13+6)) | P13: =IFERROR(I13/H13,"") | Q13: =IFERROR(K13/J13,"") | R13: =IFERROR(M13/L13,"")
A14: =A13+7 | B14: =IF(A14="","",TEXT(A14,"d mmm")) | C14: =IF($A14<Setup!$C$9,"",SUMIFS('Daily Log'!$Q$4:$Q$369,'Daily Log'!$A$4:$A$369,">="&$A14,'Daily Log'!$A$4:$A$369,"<="&$A14+6)) | D14: =IF($A14<Setup!$C$9,"",SUMIFS('Daily Log'!$C$4:$C$369,'Daily Log'!$A$4:$A$369,">="&$A14,'Daily Log'!$A$4:$A$369,"<="&$A14+6)) | E14: =IF($A14<Setup!$C$9,"",SUMIFS('Daily Log'!$D$4:$D$369,'Daily Log'!$A$4:$A$369,">="&$A14,'Daily Log'!$A$4:$A$369,"<="&$A14+6)) | F14: =IF($A14<Setup!$C$9,"",SUMIFS('Daily Log'!$E$4:$E$369,'Daily Log'!$A$4:$A$369,">="&$A14,'Daily Log'!$A$4:$A$369,"<="&$A14+6)) | G14: =IF($A14<Setup!$C$9,"",SUMIFS('Daily Log'!$F$4:$F$369,'Daily Log'!$A$4:$A$369,">="&$A14,'Daily Log'!$A$4:$A$369,"<="&$A14+6)) | H14: =IF($A14<Setup!$C$9,"",IFERROR(F14+G14,"")) | I14: =IF($A14<Setup!$C$9,"",SUMIFS('Daily Log'!$G$4:$G$369,'Daily Log'!$A$4:$A$369,">="&$A14,'Daily Log'!$A$4:$A$369,"<="&$A14+6)) | J14: =IF($A14<Setup!$C$9,"",SUMIFS('Daily Log'!$H$4:$H$369,'Daily Log'!$A$4:$A$369,">="&$A14,'Daily Log'!$A$4:$A$369,"<="&$A14+6)) | K14: =IF($A14<Setup!$C$9,"",SUMIFS('Daily Log'!$I$4:$I$369,'Daily Log'!$A$4:$A$369,">="&$A14,'Daily Log'!$A$4:$A$369,"<="&$A14+6)) | L14: =IF($A14<Setup!$C$9,"",SUMIFS('Daily Log'!$J$4:$J$369,'Daily Log'!$A$4:$A$369,">="&$A14,'Daily Log'!$A$4:$A$369,"<="&$A14+6)) | M14: =IF($A14<Setup!$C$9,"",SUMIFS('Daily Log'!$K$4:$K$369,'Daily Log'!$A$4:$A$369,">="&$A14,'Daily Log'!$A$4:$A$369,"<="&$A14+6)) | N14: =IF($A14<Setup!$C$9,"",SUMIFS('Daily Log'!$L$4:$L$369,'Daily Log'!$A$4:$A$369,">="&$A14,'Daily Log'!$A$4:$A$369,"<="&$A14+6)) | O14: =IF($A14<Setup!$C$9,"",SUMIFS('Daily Log'!$M$4:$M$369,'Daily Log'!$A$4:$A$369,">="&$A14,'Daily Log'!$A$4:$A$369,"<="&$A14+6)) | P14: =IFERROR(I14/H14,"") | Q14: =IFERROR(K14/J14,"") | R14: =IFERROR(M14/L14,"")
A15: =A14+7 | B15: =IF(A15="","",TEXT(A15,"d mmm")) | C15: =IF($A15<Setup!$C$9,"",SUMIFS('Daily Log'!$Q$4:$Q$369,'Daily Log'!$A$4:$A$369,">="&$A15,'Daily Log'!$A$4:$A$369,"<="&$A15+6)) | D15: =IF($A15<Setup!$C$9,"",SUMIFS('Daily Log'!$C$4:$C$369,'Daily Log'!$A$4:$A$369,">="&$A15,'Daily Log'!$A$4:$A$369,"<="&$A15+6)) | E15: =IF($A15<Setup!$C$9,"",SUMIFS('Daily Log'!$D$4:$D$369,'Daily Log'!$A$4:$A$369,">="&$A15,'Daily Log'!$A$4:$A$369,"<="&$A15+6)) | F15: =IF($A15<Setup!$C$9,"",SUMIFS('Daily Log'!$E$4:$E$369,'Daily Log'!$A$4:$A$369,">="&$A15,'Daily Log'!$A$4:$A$369,"<="&$A15+6)) | G15: =IF($A15<Setup!$C$9,"",SUMIFS('Daily Log'!$F$4:$F$369,'Daily Log'!$A$4:$A$369,">="&$A15,'Daily Log'!$A$4:$A$369,"<="&$A15+6)) | H15: =IF($A15<Setup!$C$9,"",IFERROR(F15+G15,"")) | I15: =IF($A15<Setup!$C$9,"",SUMIFS('Daily Log'!$G$4:$G$369,'Daily Log'!$A$4:$A$369,">="&$A15,'Daily Log'!$A$4:$A$369,"<="&$A15+6)) | J15: =IF($A15<Setup!$C$9,"",SUMIFS('Daily Log'!$H$4:$H$369,'Daily Log'!$A$4:$A$369,">="&$A15,'Daily Log'!$A$4:$A$369,"<="&$A15+6)) | K15: =IF($A15<Setup!$C$9,"",SUMIFS('Daily Log'!$I$4:$I$369,'Daily Log'!$A$4:$A$369,">="&$A15,'Daily Log'!$A$4:$A$369,"<="&$A15+6)) | L15: =IF($A15<Setup!$C$9,"",SUMIFS('Daily Log'!$J$4:$J$369,'Daily Log'!$A$4:$A$369,">="&$A15,'Daily Log'!$A$4:$A$369,"<="&$A15+6)) | M15: =IF($A15<Setup!$C$9,"",SUMIFS('Daily Log'!$K$4:$K$369,'Daily Log'!$A$4:$A$369,">="&$A15,'Daily Log'!$A$4:$A$369,"<="&$A15+6)) | N15: =IF($A15<Setup!$C$9,"",SUMIFS('Daily Log'!$L$4:$L$369,'Daily Log'!$A$4:$A$369,">="&$A15,'Daily Log'!$A$4:$A$369,"<="&$A15+6)) | O15: =IF($A15<Setup!$C$9,"",SUMIFS('Daily Log'!$M$4:$M$369,'Daily Log'!$A$4:$A$369,">="&$A15,'Daily Log'!$A$4:$A$369,"<="&$A15+6)) | P15: =IFERROR(I15/H15,"") | Q15: =IFERROR(K15/J15,"") | R15: =IFERROR(M15/L15,"")
A16: =A15+7 | B16: =IF(A16="","",TEXT(A16,"d mmm")) | C16: =IF($A16<Setup!$C$9,"",SUMIFS('Daily Log'!$Q$4:$Q$369,'Daily Log'!$A$4:$A$369,">="&$A16,'Daily Log'!$A$4:$A$369,"<="&$A16+6)) | D16: =IF($A16<Setup!$C$9,"",SUMIFS('Daily Log'!$C$4:$C$369,'Daily Log'!$A$4:$A$369,">="&$A16,'Daily Log'!$A$4:$A$369,"<="&$A16+6)) | E16: =IF($A16<Setup!$C$9,"",SUMIFS('Daily Log'!$D$4:$D$369,'Daily Log'!$A$4:$A$369,">="&$A16,'Daily Log'!$A$4:$A$369,"<="&$A16+6)) | F16: =IF($A16<Setup!$C$9,"",SUMIFS('Daily Log'!$E$4:$E$369,'Daily Log'!$A$4:$A$369,">="&$A16,'Daily Log'!$A$4:$A$369,"<="&$A16+6)) | G16: =IF($A16<Setup!$C$9,"",SUMIFS('Daily Log'!$F$4:$F$369,'Daily Log'!$A$4:$A$369,">="&$A16,'Daily Log'!$A$4:$A$369,"<="&$A16+6)) | H16: =IF($A16<Setup!$C$9,"",IFERROR(F16+G16,"")) | I16: =IF($A16<Setup!$C$9,"",SUMIFS('Daily Log'!$G$4:$G$369,'Daily Log'!$A$4:$A$369,">="&$A16,'Daily Log'!$A$4:$A$369,"<="&$A16+6)) | J16: =IF($A16<Setup!$C$9,"",SUMIFS('Daily Log'!$H$4:$H$369,'Daily Log'!$A$4:$A$369,">="&$A16,'Daily Log'!$A$4:$A$369,"<="&$A16+6)) | K16: =IF($A16<Setup!$C$9,"",SUMIFS('Daily Log'!$I$4:$I$369,'Daily Log'!$A$4:$A$369,">="&$A16,'Daily Log'!$A$4:$A$369,"<="&$A16+6)) | L16: =IF($A16<Setup!$C$9,"",SUMIFS('Daily Log'!$J$4:$J$369,'Daily Log'!$A$4:$A$369,">="&$A16,'Daily Log'!$A$4:$A$369,"<="&$A16+6)) | M16: =IF($A16<Setup!$C$9,"",SUMIFS('Daily Log'!$K$4:$K$369,'Daily Log'!$A$4:$A$369,">="&$A16,'Daily Log'!$A$4:$A$369,"<="&$A16+6)) | N16: =IF($A16<Setup!$C$9,"",SUMIFS('Daily Log'!$L$4:$L$369,'Daily Log'!$A$4:$A$369,">="&$A16,'Daily Log'!$A$4:$A$369,"<="&$A16+6)) | O16: =IF($A16<Setup!$C$9,"",SUMIFS('Daily Log'!$M$4:$M$369,'Daily Log'!$A$4:$A$369,">="&$A16,'Daily Log'!$A$4:$A$369,"<="&$A16+6)) | P16: =IFERROR(I16/H16,"") | Q16: =IFERROR(K16/J16,"") | R16: =IFERROR(M16/L16,"")
