Workbook

Sheet Start Here
A1: DEMO · THE SCOREBOARD · SAMPLE DATA — REFERENCE ONLY
A2: The work you put in, and what it turns into. Five minutes a week keeps it honest.
B4: This is a sample. Do not work in it.
B5: Every number in this file is made up, and it is here so you can see what the Scoreboard looks like once it has history in it. Your own copy starts empty — log in that one, not this one.
A8: DO THESE IN ORDER
A9: Step | B9: Tab | C9: When | D9: What you do
A10: 1 | B10: Setup | C10: Once, right now | D10: Your name, your start date, your daily standards. Two minutes, never again.
A11: 2 | B11: Daily Log | C11: Every day — 60 seconds | D11: Find today's row (it's highlighted) and fill in what you actually did.
A12: 3 | B12: Instagram Tracker | C12: Every Sunday — 5 minutes | D12: Log the week's numbers off your Professional Dashboard.
A13: 4 | B13: This Week | C13: Every Monday — 2 minutes | D13: What you hit, what you missed, and the one thing to fix this week.
A14: 5 | B14: KPI Dashboard | C14: Before every coaching call | D14: The full picture: rates, trends, and where the money's leaking.
A16: REFERENCE — open these when you need them
B17: Cheat Sheet | D17: What every number means, what a low one is telling you, and exactly what to do about it. Read it once, then whenever a number looks wrong.
B18: Weekly Rollup | D18: Feeds the charts on the dashboard. Nothing to fill in. Leave it alone.
A19: THE RULES — read once, saves you a headache
B20: Cream cells are yours. | D20: Grey cells calculate themselves. If it's grey, don't type in it.
B21: Log a zero as 0, never blank. | D21: Blank means 'didn't track'. Blanks make your averages flatter you.
B22: Don't delete columns or rows. | D22: It breaks the maths. Don't need a column? Right-click and Hide it.
B23: Backfill a missed day. | D23: A gap in the log is a lie in your numbers. Fill it in when you remember.
A25: EXAMPLE — what one good day looks like
A26: Date | B26: Reels | C26: Stories | D26: Opener DMs | E26: Follow-Ups | F26: Replies | G26: Pitched | H26: Booked
A27: Mon 15 Sep | B27: 5 | C27: 5 | D27: 20 | E27: 10 | F27: 4 | G27: 2 | H27: 1
A28: All four standards hit → the day scores 4/4, and your perfect-day streak goes up.
A30: WALKTHROUGH VIDEOS
B31: Setup + Daily Log | D31: [paste Loom link]
B32: KPI Dashboard + This Week | D32: [paste Loom link]
B33: Instagram Tracker | D33: [paste Loom link]
B34: Content Planner (Notion) | D34: [paste Loom link]

Sheet Setup
A1: DEMO · SETUP — two minutes, once · SAMPLE DATA — REFERENCE ONLY
A2: Fill in the cream cells. Every other tab reads from here.
A4: WHO THIS IS
B5: Client name | C5: Demo Client | D5: Shows on your dashboard.
B6: Coach / CSM | C6: Francis | D6: Who you report to inside The Called.
B7: Instagram handle | C7: @democlient | D7: e.g. @yourhandle
B8: Tracking start date | C8: =TODAY()-118 | D8: Day 1. This sets every date in the Daily Log.
B9: First tracking week (auto) | C9: =C8-WEEKDAY(C8,2)+1 | D9: Monday of your start week. Calculated — don't edit.
A11: YOUR DAILY STANDARDS — the floor, not the goal
B12: Reels / posts per day | C12: 5 | D12: Default 5.
B13: Stories per day | C13: 5 | D13: Default 5.
B14: Opener DMs per day | C14: 20 | D14: Default 20.
B15: Follow-up DMs per day | C15: 10 | D15: Default 10.
A17: WHAT YOU'RE PLAYING FOR
B18: Monthly cash collected goal | C18: 10000 | D18: Drives the goal tile on the dashboard.
B19: Your offer price | C19: 0 | D19: Optional — for your own maths.

Sheet Daily Log
A1: DEMO · DAILY LOG — one row per day · SAMPLE DATA — REFERENCE ONLY
A2: Your standard → | C2: =Setup!$C$12 | D2: =Setup!$C$13 | E2: =Setup!$C$14 | F2: =Setup!$C$15 | H2: Today's row is highlighted. Log a zero as 0 — blank means you didn't track.
A3: Date | B3: Day | C3: Reels / Posts | D3: Stories | E3: Opener DMs Sent | F3: Follow-Up DMs Sent | G3: Replies | H3: Calls Pitched | I3: Calls Booked | J3: Calls Showed | K3: Closes | L3: Cash Collected | M3: Revenue Generated | N3: Followers (end of day) | O3: Standards Hit (of 4) | P3: Notes | Q3: Logged? (auto) | R3: Day Streak | S3: Perfect Streak | T3: Logged on (auto)
A4: =Setup!$C$8 | B4: =IF(A4="","",TEXT(A4,"ddd")) | C4: 6 | D4: 7 | E4: 26 | F4: 13 | G4: 7 | H4: 5 | I4: 1 | J4: 0 | K4: 0 | L4: 0 | M4: 0 | N4: 3205 | O4: =IF($Q4=0,"",IF(C4>=C$2,1,0)+IF(D4>=D$2,1,0)+IF(E4>=E$2,1,0)+IF(F4>=F$2,1,0)) | P4: First week — finding the rhythm | Q4: =IF(COUNT(C4:M4)>0,1,0) | R4: =IF(Q4=0,0,1) | S4: =IF(O4="",0,IF(O4=4,1,0)) | T4: =IF(Q4=1,A4,"")
A5: =A4+1 | B5: =IF(A5="","",TEXT(A5,"ddd")) | C5: 6 | D5: 7 | E5: 24 | F5: 11 | G5: 5 | H5: 2 | I5: 0 | J5: 0 | K5: 0 | L5: 0 | M5: 0 | N5: 3236 | O5: =IF($Q5=0,"",IF(C5>=C$2,1,0)+IF(D5>=D$2,1,0)+IF(E5>=E$2,1,0)+IF(F5>=F$2,1,0)) | Q5: =IF(COUNT(C5:M5)>0,1,0) | R5: =IF(Q5=0,0,R4+1) | S5: =IF(O5="",0,IF(O5=4,S4+1,0)) | T5: =IF(Q5=1,A5,"")
A6: =A5+1 | B6: =IF(A6="","",TEXT(A6,"ddd")) | C6: 2 | D6: 2 | E6: 8 | F6: 5 | G6: 3 | H6: 2 | I6: 1 | J6: 0 | K6: 0 | L6: 0 | M6: 0 | N6: 3250 | O6: =IF($Q6=0,"",IF(C6>=C$2,1,0)+IF(D6>=D$2,1,0)+IF(E6>=E$2,1,0)+IF(F6>=F$2,1,0)) | Q6: =IF(COUNT(C6:M6)>0,1,0) | R6: =IF(Q6=0,0,R5+1) | S6: =IF(O6="",0,IF(O6=4,S5+1,0)) | T6: =IF(Q6=1,A6,"")
A7: =A6+1 | B7: =IF(A7="","",TEXT(A7,"ddd")) | C7: 2 | D7: 2 | E7: 9 | F7: 4 | G7: 2 | H7: 1 | I7: 0 | J7: 1 | K7: 0 | L7: 0 | M7: 0 | N7: 3273 | O7: =IF($Q7=0,"",IF(C7>=C$2,1,0)+IF(D7>=D$2,1,0)+IF(E7>=E$2,1,0)+IF(F7>=F$2,1,0)) | Q7: =IF(COUNT(C7:M7)>0,1,0) | R7: =IF(Q7=0,0,R6+1) | S7: =IF(O7="",0,IF(O7=4,S6+1,0)) | T7: =IF(Q7=1,A7,"")
A8: =A7+1 | B8: =IF(A8="","",TEXT(A8,"ddd")) | C8: 7 | D8: 5 | E8: 24 | F8: 11 | G8: 7 | H8: 4 | I8: 1 | J8: 0 | K8: 0 | L8: 0 | M8: 0 | N8: 3296 | O8: =IF($Q8=0,"",IF(C8>=C$2,1,0)+IF(D8>=D$2,1,0)+IF(E8>=E$2,1,0)+IF(F8>=F$2,1,0)) | Q8: =IF(COUNT(C8:M8)>0,1,0) | R8: =IF(Q8=0,0,R7+1) | S8: =IF(O8="",0,IF(O8=4,S7+1,0)) | T8: =IF(Q8=1,A8,"")
A9: =A8+1 | B9: =IF(A9="","",TEXT(A9,"ddd")) | C9: 7 | D9: 6 | E9: 23 | F9: 10 | G9: 7 | H9: 3 | I9: 1 | J9: 1 | K9: 1 | L9: 1500 | M9: 1500 | N9: 3308 | O9: =IF($Q9=0,"",IF(C9>=C$2,1,0)+IF(D9>=D$2,1,0)+IF(E9>=E$2,1,0)+IF(F9>=F$2,1,0)) | Q9: =IF(COUNT(C9:M9)>0,1,0) | R9: =IF(Q9=0,0,R8+1) | S9: =IF(O9="",0,IF(O9=4,S8+1,0)) | T9: =IF(Q9=1,A9,"")
A10: =A9+1 | B10: =IF(A10="","",TEXT(A10,"ddd")) | C10: 6 | D10: 6 | E10: 20 | F10: 10 | G10: 7 | H10: 3 | I10: 1 | J10: 0 | K10: 0 | L10: 0 | M10: 0 | N10: 3332 | O10: =IF($Q10=0,"",IF(C10>=C$2,1,0)+IF(D10>=D$2,1,0)+IF(E10>=E$2,1,0)+IF(F10>=F$2,1,0)) | Q10: =IF(COUNT(C10:M10)>0,1,0) | R10: =IF(Q10=0,0,R9+1) | S10: =IF(O10="",0,IF(O10=4,S9+1,0)) | T10: =IF(Q10=1,A10,"")
A11: =A10+1 | B11: =IF(A11="","",TEXT(A11,"ddd")) | C11: 6 | D11: 7 | E11: 23 | F11: 13 | G11: 5 | H11: 3 | I11: 1 | J11: 1 | K11: 1 | L11: 2000 | M11: 2000 | N11: 3354 | O11: =IF($Q11=0,"",IF(C11>=C$2,1,0)+IF(D11>=D$2,1,0)+IF(E11>=E$2,1,0)+IF(F11>=F$2,1,0)) | Q11: =IF(COUNT(C11:M11)>0,1,0) | R11: =IF(Q11=0,0,R10+1) | S11: =IF(O11="",0,IF(O11=4,S10+1,0)) | T11: =IF(Q11=1,A11,"")
A12: =A11+1 | B12: =IF(A12="","",TEXT(A12,"ddd")) | C12: 5 | D12: 5 | E12: 21 | F12: 10 | G12: 4 | H12: 2 | I12: 1 | J12: 1 | K12: 1 | L12: 2000 | M12: 3500 | N12: 3367 | O12: =IF($Q12=0,"",IF(C12>=C$2,1,0)+IF(D12>=D$2,1,0)+IF(E12>=E$2,1,0)+IF(F12>=F$2,1,0)) | Q12: =IF(COUNT(C12:M12)>0,1,0) | R12: =IF(Q12=0,0,R11+1) | S12: =IF(O12="",0,IF(O12=4,S11+1,0)) | T12: =IF(Q12=1,A12,"")
A13: =A12+1 | B13: =IF(A13="","",TEXT(A13,"ddd")) | C13: 2 | D13: 2 | E13: 8 | F13: 4 | G13: 2 | H13: 1 | I13: 0 | J13: 0 | K13: 0 | L13: 0 | M13: 0 | N13: 3394 | O13: =IF($Q13=0,"",IF(C13>=C$2,1,0)+IF(D13>=D$2,1,0)+IF(E13>=E$2,1,0)+IF(F13>=F$2,1,0)) | Q13: =IF(COUNT(C13:M13)>0,1,0) | R13: =IF(Q13=0,0,R12+1) | S13: =IF(O13="",0,IF(O13=4,S12+1,0)) | T13: =IF(Q13=1,A13,"")
A14: =A13+1 | B14: =IF(A14="","",TEXT(A14,"ddd")) | C14: 2 | D14: 2 | E14: 7 | F14: 4 | G14: 2 | H14: 1 | I14: 0 | J14: 0 | K14: 0 | L14: 0 | M14: 0 | N14: 3406 | O14: =IF($Q14=0,"",IF(C14>=C$2,1,0)+IF(D14>=D$2,1,0)+IF(E14>=E$2,1,0)+IF(F14>=F$2,1,0)) | Q14: =IF(COUNT(C14:M14)>0,1,0) | R14: =IF(Q14=0,0,R13+1) | S14: =IF(O14="",0,IF(O14=4,S13+1,0)) | T14: =IF(Q14=1,A14,"")
A15: =A14+1 | B15: =IF(A15="","",TEXT(A15,"ddd")) | C15: 5 | D15: 5 | E15: 21 | F15: 13 | G15: 5 | H15: 3 | I15: 1 | J15: 0 | K15: 0 | L15: 0 | M15: 0 | N15: 3424 | O15: =IF($Q15=0,"",IF(C15>=C$2,1,0)+IF(D15>=D$2,1,0)+IF(E15>=E$2,1,0)+IF(F15>=F$2,1,0)) | Q15: =IF(COUNT(C15:M15)>0,1,0) | R15: =IF(Q15=0,0,R14+1) | S15: =IF(O15="",0,IF(O15=4,S14+1,0)) | T15: =IF(Q15=1,A15,"")
A16: =A15+1 | B16: =IF(A16="","",TEXT(A16,"ddd")) | C16: 6 | D16: 5 | E16: 20 | F16: 10 | G16: 5 | H16: 3 | I16: 1 | J16: 1 | K16: 0 | L16: 0 | M16: 0 | N16: 3437 | O16: =IF($Q16=0,"",IF(C16>=C$2,1,0)+IF(D16>=D$2,1,0)+IF(E16>=E$2,1,0)+IF(F16>=F$2,1,0)) | Q16: =IF(COUNT(C16:M16)>0,1,0) | R16: =IF(Q16=0,0,R15+1) | S16: =IF(O16="",0,IF(O16=4,S15+1,0)) | T16: =IF(Q16=1,A16,"")
... A38: =A37+1 | B38: =IF(A38="","",TEXT(A38,"ddd")) | C38: 7 | D38: 5 | E38: 21 | F38: 11 | G38: 5 | H38: 2 | I38: 1 | J38: 1 | K38: 0 | L38: 0 | M38: 0 | N38: 3870 | O38: =IF($Q38=0,"",IF(C38>=C$2,1,0)+IF(D38>=D$2,1,0)+IF(E38>=E$2,1,0)+IF(F38>=F$2,1,0)) | Q38: =IF(COUNT(C38:M38)>0,1,0) | R38: =IF(Q38=0,0,R37+1) | S38: =IF(O38="",0,IF(O38=4,S37+1,0)) | T38: =IF(Q38=1,A38,"")
A39: =A38+1 | B39: =IF(A39="","",TEXT(A39,"ddd")) | C39: 5 | D39: 5 | E39: 19 | F39: 1 | G39: 2 | H39: 1 | I39: 0 | J39: 1 | K39: 1 | L39: 1500 | M39: 1500 | N39: 3882 | O39: =IF($Q39=0,"",IF(C39>=C$2,1,0)+IF(D39>=D$2,1,0)+IF(E39>=E$2,1,0)+IF(F39>=F$2,1,0)) | P39: Slipping on follow-ups, got busy with delivery | Q39: =IF(COUNT(C39:M39)>0,1,0) | R39: =IF(Q39=0,0,R38+1) | S39: =IF(O39="",0,IF(O39=4,S38+1,0)) | T39: =IF(Q39=1,A39,"")
A40: =A39+1 | B40: =IF(A40="","",TEXT(A40,"ddd")) | C40: 6 | D40: 5 | E40: 22 | F40: 3 | G40: 3 | H40: 1 | I40: 0 | J40: 0 | K40: 0 | L40: 0 | M40: 0 | N40: 3896 | O40: =IF($Q40=0,"",IF(C40>=C$2,1,0)+IF(D40>=D$2,1,0)+IF(E40>=E$2,1,0)+IF(F40>=F$2,1,0)) | Q40: =IF(COUNT(C40:M40)>0,1,0) | R40: =IF(Q40=0,0,R39+1) | S40: =IF(O40="",0,IF(O40=4,S39+1,0)) | T40: =IF(Q40=1,A40,"")
A41: =A40+1 | B41: =IF(A41="","",TEXT(A41,"ddd")) | C41: 2 | D41: 1 | E41: 7 | F41: 1 | G41: 1 | H41: 1 | I41: 0 | J41: 0 | K41: 0 | L41: 0 | M41: 0 | N41: 3908 | O41: =IF($Q41=0,"",IF(C41>=C$2,1,0)+IF(D41>=D$2,1,0)+IF(E41>=E$2,1,0)+IF(F41>=F$2,1,0)) | Q41: =IF(COUNT(C41:M41)>0,1,0) | R41: =IF(Q41=0,0,R40+1) | S41: =IF(O41="",0,IF(O41=4,S40+1,0)) | T41: =IF(Q41=1,A41,"")
A42: =A41+1 | B42: =IF(A42="","",TEXT(A42,"ddd")) | C42: 0 | D42: 0 | E42: 0 | F42: 0 | G42: 0 | H42: 0 | I42: 0 | J42: 0 | K42: 0 | L42: 0 | M42: 0 | N42: 3908 | O42: =IF($Q42=0,"",IF(C42>=C$2,1,0)+IF(D42>=D$2,1,0)+IF(E42>=E$2,1,0)+IF(F42>=F$2,1,0)) | P42: Travel day, nothing done | Q42: =IF(COUNT(C42:M42)>0,1,0) | R42: =IF(Q42=0,0,R41+1) | S42: =IF(O42="",0,IF(O42=4,S41+1,0)) | T42: =IF(Q42=1,A42,"")
A43: =A42+1 | B43: =IF(A43="","",TEXT(A43,"ddd")) | C43: 5 | D43: 4 | E43: 23 | F43: 1 | G43: 2 | H43: 1 | I43: 0 | J43: 0 | K43: 0 | L43: 0 | M43: 0 | N43: 3920 | O43: =IF($Q43=0,"",IF(C43>=C$2,1,0)+IF(D43>=D$2,1,0)+IF(E43>=E$2,1,0)+IF(F43>=F$2,1,0)) | Q43: =IF(COUNT(C43:M43)>0,1,0) | R43: =IF(Q43=0,0,R42+1) | S43: =IF(O43="",0,IF(O43=4,S42+1,0)) | T43: =IF(Q43=1,A43,"")
A44: =A43+1 | B44: =IF(A44="","",TEXT(A44,"ddd")) | C44: 5 | D44: 4 | E44: 21 | F44: 1 | G44: 2 | H44: 1 | I44: 0 | J44: 0 | K44: 0 | L44: 0 | M44: 0 | N44: 3924 | O44: =IF($Q44=0,"",IF(C44>=C$2,1,0)+IF(D44>=D$2,1,0)+IF(E44>=E$2,1,0)+IF(F44>=F$2,1,0)) | Q44: =IF(COUNT(C44:M44)>0,1,0) | R44: =IF(Q44=0,0,R43+1) | S44: =IF(O44="",0,IF(O44=4,S43+1,0)) | T44: =IF(Q44=1,A44,"")
A45: =A44+1 | B45: =IF(A45="","",TEXT(A45,"ddd")) | C45: 4 | D45: 5 | E45: 20 | F45: 2 | G45: 2 | H45: 1 | I45: 0 | J45: 0 | K45: 0 | L45: 0 | M45: 0 | N45: 3936 | O45: =IF($Q45=0,"",IF(C45>=C$2,1,0)+IF(D45>=D$2,1,0)+IF(E45>=E$2,1,0)+IF(F45>=F$2,1,0)) | Q45: =IF(COUNT(C45:M45)>0,1,0) | R45: =IF(Q45=0,0,R44+1) | S45: =IF(O45="",0,IF(O45=4,S44+1,0)) | T45: =IF(Q45=1,A45,"")
A46: =A45+1 | B46: =IF(A46="","",TEXT(A46,"ddd")) | C46: 6 | D46: 5 | E46: 21 | F46: 4 | G46: 3 | H46: 1 | I46: 0 | J46: 0 | K46: 0 | L46: 0 | M46: 0 | N46: 3947 | O46: =IF($Q46=0,"",IF(C46>=C$2,1,0)+IF(D46>=D$2,1,0)+IF(E46>=E$2,1,0)+IF(F46>=F$2,1,0)) | Q46: =IF(COUNT(C46:M46)>0,1,0) | R46: =IF(Q46=0,0,R45+1) | S46: =IF(O46="",0,IF(O46=4,S45+1,0)) | T46: =IF(Q46=1,A46,"")
A47: =A46+1 | B47: =IF(A47="","",TEXT(A47,"ddd")) | C47: 6 | D47: 5 | E47: 20 | F47: 2 | G47: 2 | H47: 1 | I47: 0 | J47: 0 | K47: 0 | L47: 0 | M47: 0 | N47: 3955 | O47: =IF($Q47=0,"",IF(C47>=C$2,1,0)+IF(D47>=D$2,1,0)+IF(E47>=E$2,1,0)+IF(F47>=F$2,1,0)) | Q47: =IF(COUNT(C47:M47)>0,1,0) | R47: =IF(Q47=0,0,R46+1) | S47: =IF(O47="",0,IF(O47=4,S46+1,0)) | T47: =IF(Q47=1,A47,"")
A48: =A47+1 | B48: =IF(A48="","",TEXT(A48,"ddd")) | C48: 2 | D48: 1 | E48: 8 | F48: 1 | G48: 1 | H48: 0 | I48: 0 | J48: 0 | K48: 0 | L48: 0 | M48: 0 | N48: 3963 | O48: =IF($Q48=0,"",IF(C48>=C$2,1,0)+IF(D48>=D$2,1,0)+IF(E48>=E$2,1,0)+IF(F48>=F$2,1,0)) | Q48: =IF(COUNT(C48:M48)>0,1,0) | R48: =IF(Q48=0,0,R47+1) | S48: =IF(O48="",0,IF(O48=4,S47+1,0)) | T48: =IF(Q48=1,A48,"")
A49: =A48+1 | B49: =IF(A49="","",TEXT(A49,"ddd")) | C49: 2 | D49: 1 | E49: 7 | F49: 1 | G49: 1 | H49: 0 | I49: 0 | J49: 0 | K49: 0 | L49: 0 | M49: 0 | N49: 3967 | O49: =IF($Q49=0,"",IF(C49>=C$2,1,0)+IF(D49>=D$2,1,0)+IF(E49>=E$2,1,0)+IF(F49>=F$2,1,0)) | Q49: =IF(COUNT(C49:M49)>0,1,0) | R49: =IF(Q49=0,0,R48+1) | S49: =IF(O49="",0,IF(O49=4,S48+1,0)) | T49: =IF(Q49=1,A49,"")
A50: =A49+1 | B50: =IF(A50="","",TEXT(A50,"ddd")) | C50: 6 | D50: 3 | E50: 22 | F50: 4 | G50: 3 | H50: 2 | I50: 0 | J50: 0 | K50: 0 | L50: 0 | M50: 0 | N50: 3972 | O50: =IF($Q50=0,"",IF(C50>=C$2,1,0)+IF(D50>=D$2,1,0)+IF(E50>=E$2,1,0)+IF(F50>=F$2,1,0)) | Q50: =IF(COUNT(C50:M50)>0,1,0) | R50: =IF(Q50=0,0,R49+1) | S50: =IF(O50="",0,IF(O50=4,S49+1,0)) | T50: =IF(Q50=1,A50,"")
A51: =A50+1 | B51: =IF(A51="","",TEXT(A51,"ddd")) | C51: 6 | D51: 3 | E51: 18 | F51: 4 | G51: 2 | H51: 1 | I51: 0 | J51: 0 | K51: 0 | L51: 0 | M51: 0 | N51: 3980 | O51: =IF($Q51=0,"",IF(C51>=C$2,1,0)+IF(D51>=D$2,1,0)+IF(E51>=E$2,1,0)+IF(F51>=F$2,1,0)) | Q51: =IF(COUNT(C51:M51)>0,1,0) | R51: =IF(Q51=0,0,R50+1) | S51: =IF(O51="",0,IF(O51=4,S50+1,0)) | T51: =IF(Q51=1,A51,"")
A52: =A51+1 | B52: =IF(A52="","",TEXT(A52,"ddd")) | C52: 4 | D52: 4 | E52: 21 | F52: 2 | G52: 2 | H52: 1 | I52: 0 | J52: 0 | K52: 0 | L52: 0 | M52: 0 | N52: 3991 | O52: =IF($Q52=0,"",IF(C52>=C$2,1,0)+IF(D52>=D$2,1,0)+IF(E52>=E$2,1,0)+IF(F52>=F$2,1,0)) | Q52: =IF(COUNT(C52:M52)>0,1,0) | R52: =IF(Q52=0,0,R51+1) | S52: =IF(O52="",0,IF(O52=4,S51+1,0)) | T52: =IF(Q52=1,A52,"")
A53: =A52+1 | B53: =IF(A53="","",TEXT(A53,"ddd")) | C53: 6 | D53: 4 | E53: 18 | F53: 2 | G53: 2 | H53: 1 | I53: 0 | J53: 0 | K53: 0 | L53: 0 | M53: 0 | N53: 3995 | O53: =IF($Q53=0,"",IF(C53>=C$2,1,0)+IF(D53>=D$2,1,0)+IF(E53>=E$2,1,0)+IF(F53>=F$2,1,0)) | Q53: =IF(COUNT(C53:M53)>0,1,0) | R53: =IF(Q53=0,0,R52+1) | S53: =IF(O53="",0,IF(O53=4,S52+1,0)) | T53: =IF(Q53=1,A53,"")
A54: =A53+1 | B54: =IF(A54="","",TEXT(A54,"ddd")) | C54: 4 | D54: 3 | E54: 19 | F54: 2 | G54: 2 | H54: 1 | I54: 0 | J54: 0 | K54: 0 | L54: 0 | M54: 0 | N54: 4002 | O54: =IF($Q54=0,"",IF(C54>=C$2,1,0)+IF(D54>=D$2,1,0)+IF(E54>=E$2,1,0)+IF(F54>=F$2,1,0)) | Q54: =IF(COUNT(C54:M54)>0,1,0) | R54: =IF(Q54=0,0,R53+1) | S54: =IF(O54="",0,IF(O54=4,S53+1,0)) | T54: =IF(Q54=1,A54,"")
... A73: =A72+1 | B73: =IF(A73="","",TEXT(A73,"ddd")) | C73: 5 | D73: 5 | E73: 25 | F73: 8 | G73: 4 | H73: 2 | I73: 1 | J73: 1 | K73: 0 | L73: 0 | M73: 0 | N73: 4265 | O73: =IF($Q73=0,"",IF(C73>=C$2,1,0)+IF(D73>=D$2,1,0)+IF(E73>=E$2,1,0)+IF(F73>=F$2,1,0)) | Q73: =IF(COUNT(C73:M73)>0,1,0) | R73: =IF(Q73=0,0,R72+1) | S73: =IF(O73="",0,IF(O73=4,S72+1,0)) | T73: =IF(Q73=1,A73,"")
A74: =A73+1 | B74: =IF(A74="","",TEXT(A74,"ddd")) | C74: 7 | D74: 4 | E74: 25 | F74: 6 | G74: 6 | H74: 4 | I74: 1 | J74: 1 | K74: 0 | L74: 0 | M74: 0 | N74: 4282 | O74: =IF($Q74=0,"",IF(C74>=C$2,1,0)+IF(D74>=D$2,1,0)+IF(E74>=E$2,1,0)+IF(F74>=F$2,1,0)) | P74: Coach flagged follow-ups on our call — fixing it | Q74: =IF(COUNT(C74:M74)>0,1,0) | R74: =IF(Q74=0,0,R73+1) | S74: =IF(O74="",0,IF(O74=4,S73+1,0)) | T74: =IF(Q74=1,A74,"")
A75: =A74+1 | B75: =IF(A75="","",TEXT(A75,"ddd")) | C75: 6 | D75: 5 | E75: 24 | F75: 6 | G75: 5 | H75: 3 | I75: 1 | J75: 1 | K75: 0 | L75: 0 | M75: 0 | N75: 4301 | O75: =IF($Q75=0,"",IF(C75>=C$2,1,0)+IF(D75>=D$2,1,0)+IF(E75>=E$2,1,0)+IF(F75>=F$2,1,0)) | Q75: =IF(COUNT(C75:M75)>0,1,0) | R75: =IF(Q75=0,0,R74+1) | S75: =IF(O75="",0,IF(O75=4,S74+1,0)) | T75: =IF(Q75=1,A75,"")
A76: =A75+1 | B76: =IF(A76="","",TEXT(A76,"ddd")) | C76: 2 | D76: 2 | E76: 8 | F76: 3 | G76: 2 | H76: 1 | I76: 0 | J76: 1 | K76: 0 | L76: 0 | M76: 0 | N76: 4312 | O76: =IF($Q76=0,"",IF(C76>=C$2,1,0)+IF(D76>=D$2,1,0)+IF(E76>=E$2,1,0)+IF(F76>=F$2,1,0)) | Q76: =IF(COUNT(C76:M76)>0,1,0) | R76: =IF(Q76=0,0,R75+1) | S76: =IF(O76="",0,IF(O76=4,S75+1,0)) | T76: =IF(Q76=1,A76,"")
A77: =A76+1 | B77: =IF(A77="","",TEXT(A77,"ddd")) | C77: 0 | D77: 0 | E77: 0 | F77: 0 | G77: 0 | H77: 0 | I77: 0 | J77: 0 | K77: 0 | L77: 0 | M77: 0 | N77: 4312 | O77: =IF($Q77=0,"",IF(C77>=C$2,1,0)+IF(D77>=D$2,1,0)+IF(E77>=E$2,1,0)+IF(F77>=F$2,1,0)) | Q77: =IF(COUNT(C77:M77)>0,1,0) | R77: =IF(Q77=0,0,R76+1) | S77: =IF(O77="",0,IF(O77=4,S76+1,0)) | T77: =IF(Q77=1,A77,"")
A78: =A77+1 | B78: =IF(A78="","",TEXT(A78,"ddd")) | C78: 7 | D78: 6 | E78: 25 | F78: 6 | G78: 4 | H78: 3 | I78: 1 | J78: 0 | K78: 0 | L78: 0 | M78: 0 | N78: 4326 | O78: =IF($Q78=0,"",IF(C78>=C$2,1,0)+IF(D78>=D$2,1,0)+IF(E78>=E$2,1,0)+IF(F78>=F$2,1,0)) | Q78: =IF(COUNT(C78:M78)>0,1,0) | R78: =IF(Q78=0,0,R77+1) | S78: =IF(O78="",0,IF(O78=4,S77+1,0)) | T78: =IF(Q78=1,A78,"")
A79: =A78+1 | B79: =IF(A79="","",TEXT(A79,"ddd")) | C79: 6 | D79: 6 | E79: 24 | F79: 6 | G79: 4 | H79: 2 | I79: 0 | J79: 1 | K79: 0 | L79: 0 | M79: 0 | N79: 4351 | O79: =IF($Q79=0,"",IF(C79>=C$2,1,0)+IF(D79>=D$2,1,0)+IF(E79>=E$2,1,0)+IF(F79>=F$2,1,0)) | Q79: =IF(COUNT(C79:M79)>0,1,0) | R79: =IF(Q79=0,0,R78+1) | S79: =IF(O79="",0,IF(O79=4,S78+1,0)) | T79: =IF(Q79=1,A79,"")
...

Sheet This Week
A1: DEMO · THIS WEEK · SAMPLE DATA — REFERENCE ONLY
A2: ="Week of "&TEXT(B3,"d mmm")&" — day "&D3&" of 7. Last week: "&TEXT(F3,"d mmm")&" to "&TEXT(G3,"d mmm")
A3: Week starts | B3: =TODAY()-WEEKDAY(TODAY(),2)+1 | C3: Day of week | D3: =TODAY()-B3+1 | E3: Last week | F3: =B3-7 | G3: =B3-1
A5: =IF(SUM(B10:B13)=0,"Log a couple of days and this line tells you what to fix first.",IF(MIN($F$10:$F$13)>=1,"Every standard is at or ahead of pace. Hold it — and push volume.","Fix this first: "&INDEX($A$10:$A$13,MATCH(MIN($F$10:$F$13),$F$10:$F$13,0))&" — you are at "&TEXT(MIN($F$10:$F$13),"0%")&" of your target for end of today."))
A6: =IF(COUNT('Weekly Rollup'!$C$4:$C$16)<3,"Three weeks in, this line names the weakest step in your funnel.",IF(COUNT($D$27:$D$31)=0,"Log some calls and this line compares your rates to your average.",IF(MIN($D$27:$D$31)>=0,"Every rate is at or above your average this week — so push volume.","Biggest drop vs your average: "&INDEX($A$27:$A$31,MATCH(MIN($D$27:$D$31),$D$27:$D$31,0))&", "&TEXT(ABS(MIN($D$27:$D$31)),"0.0%")&" below your usual.")))
A8: THE WORK — this part you control
A9: Standard | B9: This week so far | C9: Target by end of today | D9: Ahead / behind | E9: Weekly target | F9: % of pace | G9: Next week: aim per day
A10: Reels / posts | B10: =SUMIFS('Daily Log'!$C$4:$C$369,'Daily Log'!$A$4:$A$369,">="&$B$3,'Daily Log'!$A$4:$A$369,"<="&TODAY()) | C10: =Setup!$C$12*$D$3 | D10: =B10-C10 | E10: =Setup!$C$12*7 | F10: =IFERROR(B10/C10,0) | G10: =IF(F10>=1,ROUND(Setup!$C$12*1.1,0),Setup!$C$12)
A11: Stories | B11: =SUMIFS('Daily Log'!$D$4:$D$369,'Daily Log'!$A$4:$A$369,">="&$B$3,'Daily Log'!$A$4:$A$369,"<="&TODAY()) | C11: =Setup!$C$13*$D$3 | D11: =B11-C11 | E11: =Setup!$C$13*7 | F11: =IFERROR(B11/C11,0) | G11: =IF(F11>=1,ROUND(Setup!$C$13*1.1,0),Setup!$C$13)
A12: Opener DMs | B12: =SUMIFS('Daily Log'!$E$4:$E$369,'Daily Log'!$A$4:$A$369,">="&$B$3,'Daily Log'!$A$4:$A$369,"<="&TODAY()) | C12: =Setup!$C$14*$D$3 | D12: =B12-C12 | E12: =Setup!$C$14*7 | F12: =IFERROR(B12/C12,0) | G12: =IF(F12>=1,ROUND(Setup!$C$14*1.1,0),Setup!$C$14)
A13: Follow-up DMs | B13: =SUMIFS('Daily Log'!$F$4:$F$369,'Daily Log'!$A$4:$A$369,">="&$B$3,'Daily Log'!$A$4:$A$369,"<="&TODAY()) | C13: =Setup!$C$15*$D$3 | D13: =B13-C13 | E13: =Setup!$C$15*7 | F13: =IFERROR(B13/C13,0) | G13: =IF(F13>=1,ROUND(Setup!$C$15*1.1,0),Setup!$C$15)
A15: THE RESULT — this part follows
A16: Metric | B16: This week so far | C16: Last week | D16: Change
A17: Total DMs sent | B17: =SUMIFS('Daily Log'!$E$4:$E$369,'Daily Log'!$A$4:$A$369,">="&$B$3,'Daily Log'!$A$4:$A$369,"<="&TODAY())+SUMIFS('Daily Log'!$F$4:$F$369,'Daily Log'!$A$4:$A$369,">="&$B$3,'Daily Log'!$A$4:$A$369,"<="&TODAY()) | C17: =SUMIFS('Daily Log'!$E$4:$E$369,'Daily Log'!$A$4:$A$369,">="&$F$3,'Daily Log'!$A$4:$A$369,"<="&$G$3)+SUMIFS('Daily Log'!$F$4:$F$369,'Daily Log'!$A$4:$A$369,">="&$F$3,'Daily Log'!$A$4:$A$369,"<="&$G$3) | D17: =B17-C17
A18: Replies | B18: =SUMIFS('Daily Log'!$G$4:$G$369,'Daily Log'!$A$4:$A$369,">="&$B$3,'Daily Log'!$A$4:$A$369,"<="&TODAY()) | C18: =SUMIFS('Daily Log'!$G$4:$G$369,'Daily Log'!$A$4:$A$369,">="&$F$3,'Daily Log'!$A$4:$A$369,"<="&$G$3) | D18: =B18-C18
A19: Calls pitched | B19: =SUMIFS('Daily Log'!$H$4:$H$369,'Daily Log'!$A$4:$A$369,">="&$B$3,'Daily Log'!$A$4:$A$369,"<="&TODAY()) | C19: =SUMIFS('Daily Log'!$H$4:$H$369,'Daily Log'!$A$4:$A$369,">="&$F$3,'Daily Log'!$A$4:$A$369,"<="&$G$3) | D19: =B19-C19
A20: Calls booked | B20: =SUMIFS('Daily Log'!$I$4:$I$369,'Daily Log'!$A$4:$A$369,">="&$B$3,'Daily Log'!$A$4:$A$369,"<="&TODAY()) | C20: =SUMIFS('Daily Log'!$I$4:$I$369,'Daily Log'!$A$4:$A$369,">="&$F$3,'Daily Log'!$A$4:$A$369,"<="&$G$3) | D20: =B20-C20
A21: Calls showed | B21: =SUMIFS('Daily Log'!$J$4:$J$369,'Daily Log'!$A$4:$A$369,">="&$B$3,'Daily Log'!$A$4:$A$369,"<="&TODAY()) | C21: =SUMIFS('Daily Log'!$J$4:$J$369,'Daily Log'!$A$4:$A$369,">="&$F$3,'Daily Log'!$A$4:$A$369,"<="&$G$3) | D21: =B21-C21
A22: Closes | B22: =SUMIFS('Daily Log'!$K$4:$K$369,'Daily Log'!$A$4:$A$369,">="&$B$3,'Daily Log'!$A$4:$A$369,"<="&TODAY()) | C22: =SUMIFS('Daily Log'!$K$4:$K$369,'Daily Log'!$A$4:$A$369,">="&$F$3,'Daily Log'!$A$4:$A$369,"<="&$G$3) | D22: =B22-C22
A23: Cash collected | B23: =SUMIFS('Daily Log'!$L$4:$L$369,'Daily Log'!$A$4:$A$369,">="&$B$3,'Daily Log'!$A$4:$A$369,"<="&TODAY()) | C23: =SUMIFS('Daily Log'!$L$4:$L$369,'Daily Log'!$A$4:$A$369,">="&$F$3,'Daily Log'!$A$4:$A$369,"<="&$G$3) | D23: =B23-C23
A25: YOUR RATES vs YOUR OWN 13-WEEK AVERAGE
A26: Rate | B26: This week | C26: Your average | D26: Difference
A27: Reply rate | B27: =IFERROR(B18/B17,"") | C27: =IFERROR(AVERAGE('Weekly Rollup'!$P$4:$P$16),"") | D27: =IFERROR(B27-C27,"")
A28: Pitch rate | B28: =IFERROR(B19/B18,"") | C28: =IFERROR(AVERAGE('Weekly Rollup'!$Q$4:$Q$16),"") | D28: =IFERROR(B28-C28,"")
A29: Book rate | B29: =IFERROR(B20/B19,"") | C29: =IFERROR(AVERAGE('Weekly Rollup'!$R$4:$R$16),"") | D29: =IFERROR(B29-C29,"")
A30: Show rate | B30: =IFERROR(B21/B20,"") | C30: =IFERROR(AVERAGE('Weekly Rollup'!$S$4:$S$16),"") | D30: =IFERROR(B30-C30,"")
A31: Close rate | B31: =IFERROR(B22/B21,"") | C31: =IFERROR(AVERAGE('Weekly Rollup'!$T$4:$T$16),"") | D31: =IFERROR(B31-C31,"")
A33: AIM FOR NEXT WEEK
A34: =IF(SUM(B10:B13)=0,"Log this week first — next week's aim builds off it.","Next week, the one to protect: "&INDEX($A$10:$A$13,MATCH(MIN($F$10:$F$13),$F$10:$F$13,0))&" — "&INDEX($G$10:$G$13,MATCH(MIN($F$10:$F$13),$F$10:$F$13,0))&" a day, every day.")
A35: Standard | B35: This week | C35: Per day | D35: Week total | E35: Why
A36: Reels / posts | B36: =B10 | C36: =G10 | D36: =C36*7 | E36: =IF(F10>=1,"Held the line — push it 10%.","Missed it. Hold the standard and close the gap.")
A37: Stories | B37: =B11 | C37: =G11 | D37: =C37*7 | E37: =IF(F11>=1,"Held the line — push it 10%.","Missed it. Hold the standard and close the gap.")
A38: Opener DMs | B38: =B12 | C38: =G12 | D38: =C38*7 | E38: =IF(F12>=1,"Held the line — push it 10%.","Missed it. Hold the standard and close the gap.")
A39: Follow-up DMs | B39: =B13 | C39: =G13 | D39: =C39*7 | E39: =IF(F13>=1,"Held the line — push it 10%.","Missed it. Hold the standard and close the gap.")
A41: Per day nudges up 10% on anything you hit this week and holds the standard on anything you didn't. It's a suggestion — your actual standards live on Setup.

Sheet KPI Dashboard
A1: DEMO · KPI DASHBOARD · SAMPLE DATA — REFERENCE ONLY
A2: 100% automatic. If a number looks wrong, the fix is in the Daily Log — not here.
B4: CASH THIS MONTH | D4: % OF MONTHLY GOAL | F4: CALLS BOOKED THIS WEEK | H4: DAYS LOGGED IN A ROW | J4: PERFECT DAYS IN A ROW
A5: AT A GLANCE | B5: =SUMIFS('Daily Log'!$L$4:$L$369,'Daily Log'!$A$4:$A$369,">="&$D$10,'Daily Log'!$A$4:$A$369,"<="&$D$11) | D5: =IFERROR(B5/Setup!$C$18,0) | F5: =SUMIFS('Daily Log'!$I$4:$I$369,'Daily Log'!$A$4:$A$369,">="&$B$10,'Daily Log'!$A$4:$A$369,"<="&$B$11) | H5: =IFERROR(IF(INDEX('Daily Log'!$R$4:$R$369,MATCH(TODAY(),'Daily Log'!$A$4:$A$369,0))>0,INDEX('Daily Log'!$R$4:$R$369,MATCH(TODAY(),'Daily Log'!$A$4:$A$369,0)),INDEX('Daily Log'!$R$4:$R$369,MATCH(TODAY()-1,'Daily Log'!$A$4:$A$369,0))),0) | J5: =IFERROR(IF(INDEX('Daily Log'!$S$4:$S$369,MATCH(TODAY(),'Daily Log'!$A$4:$A$369,0))>0,INDEX('Daily Log'!$S$4:$S$369,MATCH(TODAY(),'Daily Log'!$A$4:$A$369,0)),INDEX('Daily Log'!$S$4:$S$369,MATCH(TODAY()-1,'Daily Log'!$A$4:$A$369,0))),0)
A7: ="Last entry: "&IF($G$7=-1,"nothing logged yet",IF($G$7=0,"today",IF($G$7=1,"yesterday",$G$7&" days ago"))) | G7: =IF(MAX('Daily Log'!$T$4:$T$369)=0,-1,TODAY()-MAX('Daily Log'!$T$4:$T$369))
B8: This Week | C8: Last Week | D8: This Month | E8: Last Month | F8: All Time
B9: =TEXT(B10,"d mmm")&" – "&TEXT(B11,"d mmm") | C9: =TEXT(C10,"d mmm")&" – "&TEXT(C11,"d mmm") | D9: =TEXT(D10,"d mmm")&" – "&TEXT(D11,"d mmm") | E9: =TEXT(E10,"d mmm")&" – "&TEXT(E11,"d mmm") | F9: =TEXT(F10,"d mmm")&" – "&TEXT(F11,"d mmm")
A10: Period start | B10: =TODAY()-WEEKDAY(TODAY(),2)+1 | C10: =B10-7 | D10: =DATE(YEAR(TODAY()),MONTH(TODAY()),1) | E10: =EOMONTH(TODAY(),-2)+1 | F10: =Setup!$C$8
A11: Period end | B11: =TODAY() | C11: =B10-1 | D11: =TODAY() | E11: =EOMONTH(TODAY(),-1) | F11: =TODAY()
A13: ACTIVITY — what you put in
A14: Days Logged | B14: =SUMIFS('Daily Log'!$Q$4:$Q$369,'Daily Log'!$A$4:$A$369,">="&B$10,'Daily Log'!$A$4:$A$369,"<="&B$11) | C14: =SUMIFS('Daily Log'!$Q$4:$Q$369,'Daily Log'!$A$4:$A$369,">="&C$10,'Daily Log'!$A$4:$A$369,"<="&C$11) | D14: =SUMIFS('Daily Log'!$Q$4:$Q$369,'Daily Log'!$A$4:$A$369,">="&D$10,'Daily Log'!$A$4:$A$369,"<="&D$11) | E14: =SUMIFS('Daily Log'!$Q$4:$Q$369,'Daily Log'!$A$4:$A$369,">="&E$10,'Daily Log'!$A$4:$A$369,"<="&E$11) | F14: =SUMIFS('Daily Log'!$Q$4:$Q$369,'Daily Log'!$A$4:$A$369,">="&F$10,'Daily Log'!$A$4:$A$369,"<="&F$11)
A15: Reels / Posts | B15: =SUMIFS('Daily Log'!$C$4:$C$369,'Daily Log'!$A$4:$A$369,">="&B$10,'Daily Log'!$A$4:$A$369,"<="&B$11) | C15: =SUMIFS('Daily Log'!$C$4:$C$369,'Daily Log'!$A$4:$A$369,">="&C$10,'Daily Log'!$A$4:$A$369,"<="&C$11) | D15: =SUMIFS('Daily Log'!$C$4:$C$369,'Daily Log'!$A$4:$A$369,">="&D$10,'Daily Log'!$A$4:$A$369,"<="&D$11) | E15: =SUMIFS('Daily Log'!$C$4:$C$369,'Daily Log'!$A$4:$A$369,">="&E$10,'Daily Log'!$A$4:$A$369,"<="&E$11) | F15: =SUMIFS('Daily Log'!$C$4:$C$369,'Daily Log'!$A$4:$A$369,">="&F$10,'Daily Log'!$A$4:$A$369,"<="&F$11)
A16: Stories | B16: =SUMIFS('Daily Log'!$D$4:$D$369,'Daily Log'!$A$4:$A$369,">="&B$10,'Daily Log'!$A$4:$A$369,"<="&B$11) | C16: =SUMIFS('Daily Log'!$D$4:$D$369,'Daily Log'!$A$4:$A$369,">="&C$10,'Daily Log'!$A$4:$A$369,"<="&C$11) | D16: =SUMIFS('Daily Log'!$D$4:$D$369,'Daily Log'!$A$4:$A$369,">="&D$10,'Daily Log'!$A$4:$A$369,"<="&D$11) | E16: =SUMIFS('Daily Log'!$D$4:$D$369,'Daily Log'!$A$4:$A$369,">="&E$10,'Daily Log'!$A$4:$A$369,"<="&E$11) | F16: =SUMIFS('Daily Log'!$D$4:$D$369,'Daily Log'!$A$4:$A$369,">="&F$10,'Daily Log'!$A$4:$A$369,"<="&F$11)
A17: Opener DMs Sent | B17: =SUMIFS('Daily Log'!$E$4:$E$369,'Daily Log'!$A$4:$A$369,">="&B$10,'Daily Log'!$A$4:$A$369,"<="&B$11) | C17: =SUMIFS('Daily Log'!$E$4:$E$369,'Daily Log'!$A$4:$A$369,">="&C$10,'Daily Log'!$A$4:$A$369,"<="&C$11) | D17: =SUMIFS('Daily Log'!$E$4:$E$369,'Daily Log'!$A$4:$A$369,">="&D$10,'Daily Log'!$A$4:$A$369,"<="&D$11) | E17: =SUMIFS('Daily Log'!$E$4:$E$369,'Daily Log'!$A$4:$A$369,">="&E$10,'Daily Log'!$A$4:$A$369,"<="&E$11) | F17: =SUMIFS('Daily Log'!$E$4:$E$369,'Daily Log'!$A$4:$A$369,">="&F$10,'Daily Log'!$A$4:$A$369,"<="&F$11)
A18: Follow-Up DMs Sent | B18: =SUMIFS('Daily Log'!$F$4:$F$369,'Daily Log'!$A$4:$A$369,">="&B$10,'Daily Log'!$A$4:$A$369,"<="&B$11) | C18: =SUMIFS('Daily Log'!$F$4:$F$369,'Daily Log'!$A$4:$A$369,">="&C$10,'Daily Log'!$A$4:$A$369,"<="&C$11) | D18: =SUMIFS('Daily Log'!$F$4:$F$369,'Daily Log'!$A$4:$A$369,">="&D$10,'Daily Log'!$A$4:$A$369,"<="&D$11) | E18: =SUMIFS('Daily Log'!$F$4:$F$369,'Daily Log'!$A$4:$A$369,">="&E$10,'Daily Log'!$A$4:$A$369,"<="&E$11) | F18: =SUMIFS('Daily Log'!$F$4:$F$369,'Daily Log'!$A$4:$A$369,">="&F$10,'Daily Log'!$A$4:$A$369,"<="&F$11)
A19: Total DMs Sent | B19: =B17+B18 | C19: =C17+C18 | D19: =D17+D18 | E19: =E17+E18 | F19: =F17+F18
A20: Replies | B20: =SUMIFS('Daily Log'!$G$4:$G$369,'Daily Log'!$A$4:$A$369,">="&B$10,'Daily Log'!$A$4:$A$369,"<="&B$11) | C20: =SUMIFS('Daily Log'!$G$4:$G$369,'Daily Log'!$A$4:$A$369,">="&C$10,'Daily Log'!$A$4:$A$369,"<="&C$11) | D20: =SUMIFS('Daily Log'!$G$4:$G$369,'Daily Log'!$A$4:$A$369,">="&D$10,'Daily Log'!$A$4:$A$369,"<="&D$11) | E20: =SUMIFS('Daily Log'!$G$4:$G$369,'Daily Log'!$A$4:$A$369,">="&E$10,'Daily Log'!$A$4:$A$369,"<="&E$11) | F20: =SUMIFS('Daily Log'!$G$4:$G$369,'Daily Log'!$A$4:$A$369,">="&F$10,'Daily Log'!$A$4:$A$369,"<="&F$11)
A22: SALES — what it turned into
A23: Calls Pitched | B23: =SUMIFS('Daily Log'!$H$4:$H$369,'Daily Log'!$A$4:$A$369,">="&B$10,'Daily Log'!$A$4:$A$369,"<="&B$11) | C23: =SUMIFS('Daily Log'!$H$4:$H$369,'Daily Log'!$A$4:$A$369,">="&C$10,'Daily Log'!$A$4:$A$369,"<="&C$11) | D23: =SUMIFS('Daily Log'!$H$4:$H$369,'Daily Log'!$A$4:$A$369,">="&D$10,'Daily Log'!$A$4:$A$369,"<="&D$11) | E23: =SUMIFS('Daily Log'!$H$4:$H$369,'Daily Log'!$A$4:$A$369,">="&E$10,'Daily Log'!$A$4:$A$369,"<="&E$11) | F23: =SUMIFS('Daily Log'!$H$4:$H$369,'Daily Log'!$A$4:$A$369,">="&F$10,'Daily Log'!$A$4:$A$369,"<="&F$11)
A24: Calls Booked | B24: =SUMIFS('Daily Log'!$I$4:$I$369,'Daily Log'!$A$4:$A$369,">="&B$10,'Daily Log'!$A$4:$A$369,"<="&B$11) | C24: =SUMIFS('Daily Log'!$I$4:$I$369,'Daily Log'!$A$4:$A$369,">="&C$10,'Daily Log'!$A$4:$A$369,"<="&C$11) | D24: =SUMIFS('Daily Log'!$I$4:$I$369,'Daily Log'!$A$4:$A$369,">="&D$10,'Daily Log'!$A$4:$A$369,"<="&D$11) | E24: =SUMIFS('Daily Log'!$I$4:$I$369,'Daily Log'!$A$4:$A$369,">="&E$10,'Daily Log'!$A$4:$A$369,"<="&E$11) | F24: =SUMIFS('Daily Log'!$I$4:$I$369,'Daily Log'!$A$4:$A$369,">="&F$10,'Daily Log'!$A$4:$A$369,"<="&F$11)
A25: Calls Showed | B25: =SUMIFS('Daily Log'!$J$4:$J$369,'Daily Log'!$A$4:$A$369,">="&B$10,'Daily Log'!$A$4:$A$369,"<="&B$11) | C25: =SUMIFS('Daily Log'!$J$4:$J$369,'Daily Log'!$A$4:$A$369,">="&C$10,'Daily Log'!$A$4:$A$369,"<="&C$11) | D25: =SUMIFS('Daily Log'!$J$4:$J$369,'Daily Log'!$A$4:$A$369,">="&D$10,'Daily Log'!$A$4:$A$369,"<="&D$11) | E25: =SUMIFS('Daily Log'!$J$4:$J$369,'Daily Log'!$A$4:$A$369,">="&E$10,'Daily Log'!$A$4:$A$369,"<="&E$11) | F25: =SUMIFS('Daily Log'!$J$4:$J$369,'Daily Log'!$A$4:$A$369,">="&F$10,'Daily Log'!$A$4:$A$369,"<="&F$11)
A26: Closes | B26: =SUMIFS('Daily Log'!$K$4:$K$369,'Daily Log'!$A$4:$A$369,">="&B$10,'Daily Log'!$A$4:$A$369,"<="&B$11) | C26: =SUMIFS('Daily Log'!$K$4:$K$369,'Daily Log'!$A$4:$A$369,">="&C$10,'Daily Log'!$A$4:$A$369,"<="&C$11) | D26: =SUMIFS('Daily Log'!$K$4:$K$369,'Daily Log'!$A$4:$A$369,">="&D$10,'Daily Log'!$A$4:$A$369,"<="&D$11) | E26: =SUMIFS('Daily Log'!$K$4:$K$369,'Daily Log'!$A$4:$A$369,">="&E$10,'Daily Log'!$A$4:$A$369,"<="&E$11) | F26: =SUMIFS('Daily Log'!$K$4:$K$369,'Daily Log'!$A$4:$A$369,">="&F$10,'Daily Log'!$A$4:$A$369,"<="&F$11)
A27: Cash Collected | B27: =SUMIFS('Daily Log'!$L$4:$L$369,'Daily Log'!$A$4:$A$369,">="&B$10,'Daily Log'!$A$4:$A$369,"<="&B$11) | C27: =SUMIFS('Daily Log'!$L$4:$L$369,'Daily Log'!$A$4:$A$369,">="&C$10,'Daily Log'!$A$4:$A$369,"<="&C$11) | D27: =SUMIFS('Daily Log'!$L$4:$L$369,'Daily Log'!$A$4:$A$369,">="&D$10,'Daily Log'!$A$4:$A$369,"<="&D$11) | E27: =SUMIFS('Daily Log'!$L$4:$L$369,'Daily Log'!$A$4:$A$369,">="&E$10,'Daily Log'!$A$4:$A$369,"<="&E$11) | F27: =SUMIFS('Daily Log'!$L$4:$L$369,'Daily Log'!$A$4:$A$369,">="&F$10,'Daily Log'!$A$4:$A$369,"<="&F$11)
A28: Revenue Generated | B28: =SUMIFS('Daily Log'!$M$4:$M$369,'Daily Log'!$A$4:$A$369,">="&B$10,'Daily Log'!$A$4:$A$369,"<="&B$11) | C28: =SUMIFS('Daily Log'!$M$4:$M$369,'Daily Log'!$A$4:$A$369,">="&C$10,'Daily Log'!$A$4:$A$369,"<="&C$11) | D28: =SUMIFS('Daily Log'!$M$4:$M$369,'Daily Log'!$A$4:$A$369,">="&D$10,'Daily Log'!$A$4:$A$369,"<="&D$11) | E28: =SUMIFS('Daily Log'!$M$4:$M$369,'Daily Log'!$A$4:$A$369,">="&E$10,'Daily Log'!$A$4:$A$369,"<="&E$11) | F28: =SUMIFS('Daily Log'!$M$4:$M$369,'Daily Log'!$A$4:$A$369,">="&F$10,'Daily Log'!$A$4:$A$369,"<="&F$11)
A30: CONVERSION RATES — where you're actually leaking | G30: Healthy floor
A31: Reply Rate (replies ÷ DMs sent) | B31: =IFERROR(B20/B19,"") | C31: =IFERROR(C20/C19,"") | D31: =IFERROR(D20/D19,"") | E31: =IFERROR(E20/E19,"") | F31: =IFERROR(F20/F19,"") | G31: ='Cheat Sheet'!$C$11
A32: Pitch Rate (pitched ÷ replies) | B32: =IFERROR(B23/B20,"") | C32: =IFERROR(C23/C20,"") | D32: =IFERROR(D23/D20,"") | E32: =IFERROR(E23/E20,"") | F32: =IFERROR(F23/F20,"") | G32: ='Cheat Sheet'!$C$12
A33: Book Rate (booked ÷ pitched) | B33: =IFERROR(B24/B23,"") | C33: =IFERROR(C24/C23,"") | D33: =IFERROR(D24/D23,"") | E33: =IFERROR(E24/E23,"") | F33: =IFERROR(F24/F23,"") | G33: ='Cheat Sheet'!$C$13
A34: Show Rate (showed ÷ booked) | B34: =IFERROR(B25/B24,"") | C34: =IFERROR(C25/C24,"") | D34: =IFERROR(D25/D24,"") | E34: =IFERROR(E25/E24,"") | F34: =IFERROR(F25/F24,"") | G34: ='Cheat Sheet'!$C$14
A35: Close Rate (closes ÷ showed) | B35: =IFERROR(B26/B25,"") | C35: =IFERROR(C26/C25,"") | D35: =IFERROR(D26/D25,"") | E35: =IFERROR(E26/E25,"") | F35: =IFERROR(F26/F25,"") | G35: ='Cheat Sheet'!$C$15
A36: DMs per Call Booked | B36: =IFERROR(B19/B24,"") | C36: =IFERROR(C19/C24,"") | D36: =IFERROR(D19/D24,"") | E36: =IFERROR(E19/E24,"") | F36: =IFERROR(F19/F24,"")
A37: Cash per Call Booked | B37: =IFERROR(B27/B24,"") | C37: =IFERROR(C27/C24,"") | D37: =IFERROR(D27/D24,"") | E37: =IFERROR(E27/E24,"") | F37: =IFERROR(F27/F24,"")
A38: Cash per 100 DMs Sent | B38: =IFERROR(B27/B19*100,"") | C38: =IFERROR(C27/C19*100,"") | D38: =IFERROR(D27/D19*100,"") | E38: =IFERROR(E27/E19*100,"") | F38: =IFERROR(F27/F19*100,"")
A40: DAILY STANDARDS — are you holding the line? | G40: Target
A41: Avg Reels / day | B41: =IFERROR(B15/B14,"") | C41: =IFERROR(C15/C14,"") | D41: =IFERROR(D15/D14,"") | E41: =IFERROR(E15/E14,"") | F41: =IFERROR(F15/F14,"") | G41: =Setup!$C$12
A42: Avg Stories / day | B42: =IFERROR(B16/B14,"") | C42: =IFERROR(C16/C14,"") | D42: =IFERROR(D16/D14,"") | E42: =IFERROR(E16/E14,"") | F42: =IFERROR(F16/F14,"") | G42: =Setup!$C$13
A43: Avg Opener DMs / day | B43: =IFERROR(B17/B14,"") | C43: =IFERROR(C17/C14,"") | D43: =IFERROR(D17/D14,"") | E43: =IFERROR(E17/E14,"") | F43: =IFERROR(F17/F14,"") | G43: =Setup!$C$14
A44: Avg Follow-Up DMs / day | B44: =IFERROR(B18/B14,"") | C44: =IFERROR(C18/C14,"") | D44: =IFERROR(D18/D14,"") | E44: =IFERROR(E18/E14,"") | F44: =IFERROR(F18/F14,"") | G44: =Setup!$C$15
A45: Perfect Days (all 4 standards hit) | B45: =COUNTIFS('Daily Log'!$A$4:$A$369,">="&B$10,'Daily Log'!$A$4:$A$369,"<="&B$11,'Daily Log'!$O$4:$O$369,4) | C45: =COUNTIFS('Daily Log'!$A$4:$A$369,">="&C$10,'Daily Log'!$A$4:$A$369,"<="&C$11,'Daily Log'!$O$4:$O$369,4) | D45: =COUNTIFS('Daily Log'!$A$4:$A$369,">="&D$10,'Daily Log'!$A$4:$A$369,"<="&D$11,'Daily Log'!$O$4:$O$369,4) | E45: =COUNTIFS('Daily Log'!$A$4:$A$369,">="&E$10,'Daily Log'!$A$4:$A$369,"<="&E$11,'Daily Log'!$O$4:$O$369,4) | F45: =COUNTIFS('Daily Log'!$A$4:$A$369,">="&F$10,'Daily Log'!$A$4:$A$369,"<="&F$11,'Daily Log'!$O$4:$O$369,4)
A46: Standards Hit Rate | B46: =IFERROR(B45/B14,"") | C46: =IFERROR(C45/C14,"") | D46: =IFERROR(D45/D14,"") | E46: =IFERROR(E45/E14,"") | F46: =IFERROR(F45/F14,"")
...

Sheet Instagram Tracker
A1: DEMO · INSTAGRAM TRACKER · SAMPLE DATA — REFERENCE ONLY
A2: Weekly numbers off your Professional Dashboard, plus a monthly screenshot for your coach to audit.
A4: MONTHLY PROFILE CHECK — first Sunday of the month
A5: 1. Screenshot your profile — bio, follower count and the top of your grid.
A6: 2. Screenshot Professional Dashboard → Insights (last 30 days).
A7: 3. Click a box below, then Insert → Image → Image in cell, and upload.
A9: PROFILE SCREENSHOT | G9: INSIGHTS SCREENSHOT
A10: drop image here | G10: drop image here
A18: WEEKLY NUMBERS — log every Sunday night
A19: Week Starting | B19: Followers (end of week) | C19: Growth (+/-) | D19: Growth % | E19: Accounts Reached | F19: Interactions | G19: Profile Visits | H19: New Followers | I19: Link Clicks | J19: Posts (auto) | K19: Stories (auto) | L19: Reach per Post | M19: New Followers per 1k Reached | N19: Notes
A20: =Setup!$C$9 | B20: 3248 | E20: 9800 | F20: 449 | G20: 325 | H20: 68 | I20: 22 | J20: =IF($A20>TODAY(),"",SUMIFS('Daily Log'!$C$4:$C$369,'Daily Log'!$A$4:$A$369,">="&$A20,'Daily Log'!$A$4:$A$369,"<="&$A20+6)) | K20: =IF($A20>TODAY(),"",SUMIFS('Daily Log'!$D$4:$D$369,'Daily Log'!$A$4:$A$369,">="&$A20,'Daily Log'!$A$4:$A$369,"<="&$A20+6)) | L20: =IFERROR(E20/J20,"") | M20: =IFERROR(H20/E20*1000,"")
A21: =A20+7 | B21: 3344 | C21: =IF(OR(B21="",B20=""),"",B21-B20) | D21: =IF(OR(B21="",B20=""),"",IFERROR((B21-B20)/B20,"")) | E21: 11200 | F21: 554 | G21: 362 | H21: 96 | I21: 25 | J21: =IF($A21>TODAY(),"",SUMIFS('Daily Log'!$C$4:$C$369,'Daily Log'!$A$4:$A$369,">="&$A21,'Daily Log'!$A$4:$A$369,"<="&$A21+6)) | K21: =IF($A21>TODAY(),"",SUMIFS('Daily Log'!$D$4:$D$369,'Daily Log'!$A$4:$A$369,">="&$A21,'Daily Log'!$A$4:$A$369,"<="&$A21+6)) | L21: =IFERROR(E21/J21,"") | M21: =IFERROR(H21/E21*1000,"")
A22: =A21+7 | B22: 3441 | C22: =IF(OR(B22="",B21=""),"",B22-B21) | D22: =IF(OR(B22="",B21=""),"",IFERROR((B22-B21)/B21,"")) | E22: 12600 | F22: 635 | G22: 357 | H22: 97 | I22: 36 | J22: =IF($A22>TODAY(),"",SUMIFS('Daily Log'!$C$4:$C$369,'Daily Log'!$A$4:$A$369,">="&$A22,'Daily Log'!$A$4:$A$369,"<="&$A22+6)) | K22: =IF($A22>TODAY(),"",SUMIFS('Daily Log'!$D$4:$D$369,'Daily Log'!$A$4:$A$369,">="&$A22,'Daily Log'!$A$4:$A$369,"<="&$A22+6)) | L22: =IFERROR(E22/J22,"") | M22: =IFERROR(H22/E22*1000,"")
A23: =A22+7 | B23: 3531 | C23: =IF(OR(B23="",B22=""),"",B23-B22) | D23: =IF(OR(B23="",B22=""),"",IFERROR((B23-B22)/B22,"")) | E23: 13900 | F23: 729 | G23: 464 | H23: 90 | I23: 32 | J23: =IF($A23>TODAY(),"",SUMIFS('Daily Log'!$C$4:$C$369,'Daily Log'!$A$4:$A$369,">="&$A23,'Daily Log'!$A$4:$A$369,"<="&$A23+6)) | K23: =IF($A23>TODAY(),"",SUMIFS('Daily Log'!$D$4:$D$369,'Daily Log'!$A$4:$A$369,">="&$A23,'Daily Log'!$A$4:$A$369,"<="&$A23+6)) | L23: =IFERROR(E23/J23,"") | M23: =IFERROR(H23/E23*1000,"")
A24: =A23+7 | B24: 3628 | C24: =IF(OR(B24="",B23=""),"",B24-B23) | D24: =IF(OR(B24="",B23=""),"",IFERROR((B24-B23)/B23,"")) | E24: 15200 | F24: 825 | G24: 425 | H24: 97 | I24: 40 | J24: =IF($A24>TODAY(),"",SUMIFS('Daily Log'!$C$4:$C$369,'Daily Log'!$A$4:$A$369,">="&$A24,'Daily Log'!$A$4:$A$369,"<="&$A24+6)) | K24: =IF($A24>TODAY(),"",SUMIFS('Daily Log'!$D$4:$D$369,'Daily Log'!$A$4:$A$369,">="&$A24,'Daily Log'!$A$4:$A$369,"<="&$A24+6)) | L24: =IFERROR(E24/J24,"") | M24: =IFERROR(H24/E24*1000,"")
A25: =A24+7 | B25: 3705 | C25: =IF(OR(B25="",B24=""),"",B25-B24) | D25: =IF(OR(B25="",B24=""),"",IFERROR((B25-B24)/B24,"")) | E25: 11000 | F25: 578 | G25: 331 | H25: 77 | I25: 23 | J25: =IF($A25>TODAY(),"",SUMIFS('Daily Log'!$C$4:$C$369,'Daily Log'!$A$4:$A$369,">="&$A25,'Daily Log'!$A$4:$A$369,"<="&$A25+6)) | K25: =IF($A25>TODAY(),"",SUMIFS('Daily Log'!$D$4:$D$369,'Daily Log'!$A$4:$A$369,">="&$A25,'Daily Log'!$A$4:$A$369,"<="&$A25+6)) | L25: =IFERROR(E25/J25,"") | M25: =IFERROR(H25/E25*1000,"")
A26: =A25+7 | B26: 3778 | C26: =IF(OR(B26="",B25=""),"",B26-B25) | D26: =IF(OR(B26="",B25=""),"",IFERROR((B26-B25)/B25,"")) | E26: 9400 | F26: 499 | G26: 288 | H26: 73 | I26: 22 | J26: =IF($A26>TODAY(),"",SUMIFS('Daily Log'!$C$4:$C$369,'Daily Log'!$A$4:$A$369,">="&$A26,'Daily Log'!$A$4:$A$369,"<="&$A26+6)) | K26: =IF($A26>TODAY(),"",SUMIFS('Daily Log'!$D$4:$D$369,'Daily Log'!$A$4:$A$369,">="&$A26,'Daily Log'!$A$4:$A$369,"<="&$A26+6)) | L26: =IFERROR(E26/J26,"") | M26: =IFERROR(H26/E26*1000,"") | N26: Posted less this month — reach went with it
A27: =A26+7 | B27: 3849 | C27: =IF(OR(B27="",B26=""),"",B27-B26) | D27: =IF(OR(B27="",B26=""),"",IFERROR((B27-B26)/B26,"")) | E27: 8600 | F27: 466 | G27: 292 | H27: 71 | I27: 18 | J27: =IF($A27>TODAY(),"",SUMIFS('Daily Log'!$C$4:$C$369,'Daily Log'!$A$4:$A$369,">="&$A27,'Daily Log'!$A$4:$A$369,"<="&$A27+6)) | K27: =IF($A27>TODAY(),"",SUMIFS('Daily Log'!$D$4:$D$369,'Daily Log'!$A$4:$A$369,">="&$A27,'Daily Log'!$A$4:$A$369,"<="&$A27+6)) | L27: =IFERROR(E27/J27,"") | M27: =IFERROR(H27/E27*1000,"")
A28: =A27+7 | B28: 3924 | C28: =IF(OR(B28="",B27=""),"",B28-B27) | D28: =IF(OR(B28="",B27=""),"",IFERROR((B28-B27)/B27,"")) | E28: 9100 | F28: 486 | G28: 304 | H28: 75 | I28: 23 | J28: =IF($A28>TODAY(),"",SUMIFS('Daily Log'!$C$4:$C$369,'Daily Log'!$A$4:$A$369,">="&$A28,'Daily Log'!$A$4:$A$369,"<="&$A28+6)) | K28: =IF($A28>TODAY(),"",SUMIFS('Daily Log'!$D$4:$D$369,'Daily Log'!$A$4:$A$369,">="&$A28,'Daily Log'!$A$4:$A$369,"<="&$A28+6)) | L28: =IFERROR(E28/J28,"") | M28: =IFERROR(H28/E28*1000,"")
A29: =A28+7 | B29: 4017 | C29: =IF(OR(B29="",B28=""),"",B29-B28) | D29: =IF(OR(B29="",B28=""),"",IFERROR((B29-B28)/B28,"")) | E29: 11800 | F29: 621 | G29: 341 | H29: 93 | I29: 28 | J29: =IF($A29>TODAY(),"",SUMIFS('Daily Log'!$C$4:$C$369,'Daily Log'!$A$4:$A$369,">="&$A29,'Daily Log'!$A$4:$A$369,"<="&$A29+6)) | K29: =IF($A29>TODAY(),"",SUMIFS('Daily Log'!$D$4:$D$369,'Daily Log'!$A$4:$A$369,">="&$A29,'Daily Log'!$A$4:$A$369,"<="&$A29+6)) | L29: =IFERROR(E29/J29,"") | M29: =IFERROR(H29/E29*1000,"")
A30: =A29+7 | B30: 4097 | C30: =IF(OR(B30="",B29=""),"",B30-B29) | D30: =IF(OR(B30="",B29=""),"",IFERROR((B30-B29)/B29,"")) | E30: 13200 | F30: 663 | G30: 378 | H30: 80 | I30: 31 | J30: =IF($A30>TODAY(),"",SUMIFS('Daily Log'!$C$4:$C$369,'Daily Log'!$A$4:$A$369,">="&$A30,'Daily Log'!$A$4:$A$369,"<="&$A30+6)) | K30: =IF($A30>TODAY(),"",SUMIFS('Daily Log'!$D$4:$D$369,'Daily Log'!$A$4:$A$369,">="&$A30,'Daily Log'!$A$4:$A$369,"<="&$A30+6)) | L30: =IFERROR(E30/J30,"") | M30: =IFERROR(H30/E30*1000,"")
A31: =A30+7 | B31: 4206 | C31: =IF(OR(B31="",B30=""),"",B31-B30) | D31: =IF(OR(B31="",B30=""),"",IFERROR((B31-B30)/B30,"")) | E31: 15600 | F31: 722 | G31: 459 | H31: 109 | I31: 45 | J31: =IF($A31>TODAY(),"",SUMIFS('Daily Log'!$C$4:$C$369,'Daily Log'!$A$4:$A$369,">="&$A31,'Daily Log'!$A$4:$A$369,"<="&$A31+6)) | K31: =IF($A31>TODAY(),"",SUMIFS('Daily Log'!$D$4:$D$369,'Daily Log'!$A$4:$A$369,">="&$A31,'Daily Log'!$A$4:$A$369,"<="&$A31+6)) | L31: =IFERROR(E31/J31,"") | M31: =IFERROR(H31/E31*1000,"") | N31: Back to 5 a day, reach recovering
A32: =A31+7 | B32: 4313 | C32: =IF(OR(B32="",B31=""),"",B32-B31) | D32: =IF(OR(B32="",B31=""),"",IFERROR((B32-B31)/B31,"")) | E32: 17400 | F32: 919 | G32: 562 | H32: 107 | I32: 48 | J32: =IF($A32>TODAY(),"",SUMIFS('Daily Log'!$C$4:$C$369,'Daily Log'!$A$4:$A$369,">="&$A32,'Daily Log'!$A$4:$A$369,"<="&$A32+6)) | K32: =IF($A32>TODAY(),"",SUMIFS('Daily Log'!$D$4:$D$369,'Daily Log'!$A$4:$A$369,">="&$A32,'Daily Log'!$A$4:$A$369,"<="&$A32+6)) | L32: =IFERROR(E32/J32,"") | M32: =IFERROR(H32/E32*1000,"")
A33: =A32+7 | B33: 4450 | C33: =IF(OR(B33="",B32=""),"",B33-B32) | D33: =IF(OR(B33="",B32=""),"",IFERROR((B33-B32)/B32,"")) | E33: 19100 | F33: 954 | G33: 546 | H33: 137 | I33: 44 | J33: =IF($A33>TODAY(),"",SUMIFS('Daily Log'!$C$4:$C$369,'Daily Log'!$A$4:$A$369,">="&$A33,'Daily Log'!$A$4:$A$369,"<="&$A33+6)) | K33: =IF($A33>TODAY(),"",SUMIFS('Daily Log'!$D$4:$D$369,'Daily Log'!$A$4:$A$369,">="&$A33,'Daily Log'!$A$4:$A$369,"<="&$A33+6)) | L33: =IFERROR(E33/J33,"") | M33: =IFERROR(H33/E33*1000,"")
A34: =A33+7 | B34: 4632 | C34: =IF(OR(B34="",B33=""),"",B34-B33) | D34: =IF(OR(B34="",B33=""),"",IFERROR((B34-B33)/B33,"")) | E34: 21000 | F34: 1136 | G34: 659 | H34: 182 | I34: 50 | J34: =IF($A34>TODAY(),"",SUMIFS('Daily Log'!$C$4:$C$369,'Daily Log'!$A$4:$A$369,">="&$A34,'Daily Log'!$A$4:$A$369,"<="&$A34+6)) | K34: =IF($A34>TODAY(),"",SUMIFS('Daily Log'!$D$4:$D$369,'Daily Log'!$A$4:$A$369,">="&$A34,'Daily Log'!$A$4:$A$369,"<="&$A34+6)) | L34: =IFERROR(E34/J34,"") | M34: =IFERROR(H34/E34*1000,"")
A35: =A34+7 | B35: 4792 | C35: =IF(OR(B35="",B34=""),"",B35-B34) | D35: =IF(OR(B35="",B34=""),"",IFERROR((B35-B34)/B34,"")) | E35: 23500 | F35: 1266 | G35: 723 | H35: 160 | I35: 68 | J35: =IF($A35>TODAY(),"",SUMIFS('Daily Log'!$C$4:$C$369,'Daily Log'!$A$4:$A$369,">="&$A35,'Daily Log'!$A$4:$A$369,"<="&$A35+6)) | K35: =IF($A35>TODAY(),"",SUMIFS('Daily Log'!$D$4:$D$369,'Daily Log'!$A$4:$A$369,">="&$A35,'Daily Log'!$A$4:$A$369,"<="&$A35+6)) | L35: =IFERROR(E35/J35,"") | M35: =IFERROR(H35/E35*1000,"")
A36: =A35+7 | B36: 5008 | C36: =IF(OR(B36="",B35=""),"",B36-B35) | D36: =IF(OR(B36="",B35=""),"",IFERROR((B36-B35)/B35,"")) | E36: 26800 | F36: 1427 | G36: 769 | H36: 216 | I36: 56 | J36: =IF($A36>TODAY(),"",SUMIFS('Daily Log'!$C$4:$C$369,'Daily Log'!$A$4:$A$369,">="&$A36,'Daily Log'!$A$4:$A$369,"<="&$A36+6)) | K36: =IF($A36>TODAY(),"",SUMIFS('Daily Log'!$D$4:$D$369,'Daily Log'!$A$4:$A$369,">="&$A36,'Daily Log'!$A$4:$A$369,"<="&$A36+6)) | L36: =IFERROR(E36/J36,"") | M36: =IFERROR(H36/E36*1000,"")
A37: =A36+7 | C37: =IF(OR(B37="",B36=""),"",B37-B36) | D37: =IF(OR(B37="",B36=""),"",IFERROR((B37-B36)/B36,"")) | J37: =IF($A37>TODAY(),"",SUMIFS('Daily Log'!$C$4:$C$369,'Daily Log'!$A$4:$A$369,">="&$A37,'Daily Log'!$A$4:$A$369,"<="&$A37+6)) | K37: =IF($A37>TODAY(),"",SUMIFS('Daily Log'!$D$4:$D$369,'Daily Log'!$A$4:$A$369,">="&$A37,'Daily Log'!$A$4:$A$369,"<="&$A37+6)) | L37: =IFERROR(E37/J37,"") | M37: =IFERROR(H37/E37*1000,"")
A38: =A37+7 | C38: =IF(OR(B38="",B37=""),"",B38-B37) | D38: =IF(OR(B38="",B37=""),"",IFERROR((B38-B37)/B37,"")) | J38: =IF($A38>TODAY(),"",SUMIFS('Daily Log'!$C$4:$C$369,'Daily Log'!$A$4:$A$369,">="&$A38,'Daily Log'!$A$4:$A$369,"<="&$A38+6)) | K38: =IF($A38>TODAY(),"",SUMIFS('Daily Log'!$D$4:$D$369,'Daily Log'!$A$4:$A$369,">="&$A38,'Daily Log'!$A$4:$A$369,"<="&$A38+6)) | L38: =IFERROR(E38/J38,"") | M38: =IFERROR(H38/E38*1000,"")
A39: =A38+7 | C39: =IF(OR(B39="",B38=""),"",B39-B38) | D39: =IF(OR(B39="",B38=""),"",IFERROR((B39-B38)/B38,"")) | J39: =IF($A39>TODAY(),"",SUMIFS('Daily Log'!$C$4:$C$369,'Daily Log'!$A$4:$A$369,">="&$A39,'Daily Log'!$A$4:$A$369,"<="&$A39+6)) | K39: =IF($A39>TODAY(),"",SUMIFS('Daily Log'!$D$4:$D$369,'Daily Log'!$A$4:$A$369,">="&$A39,'Daily Log'!$A$4:$A$369,"<="&$A39+6)) | L39: =IFERROR(E39/J39,"") | M39: =IFERROR(H39/E39*1000,"")
A40: =A39+7 | C40: =IF(OR(B40="",B39=""),"",B40-B39) | D40: =IF(OR(B40="",B39=""),"",IFERROR((B40-B39)/B39,"")) | J40: =IF($A40>TODAY(),"",SUMIFS('Daily Log'!$C$4:$C$369,'Daily Log'!$A$4:$A$369,">="&$A40,'Daily Log'!$A$4:$A$369,"<="&$A40+6)) | K40: =IF($A40>TODAY(),"",SUMIFS('Daily Log'!$D$4:$D$369,'Daily Log'!$A$4:$A$369,">="&$A40,'Daily Log'!$A$4:$A$369,"<="&$A40+6)) | L40: =IFERROR(E40/J40,"") | M40: =IFERROR(H40/E40*1000,"")
A41: =A40+7 | C41: =IF(OR(B41="",B40=""),"",B41-B40) | D41: =IF(OR(B41="",B40=""),"",IFERROR((B41-B40)/B40,"")) | J41: =IF($A41>TODAY(),"",SUMIFS('Daily Log'!$C$4:$C$369,'Daily Log'!$A$4:$A$369,">="&$A41,'Daily Log'!$A$4:$A$369,"<="&$A41+6)) | K41: =IF($A41>TODAY(),"",SUMIFS('Daily Log'!$D$4:$D$369,'Daily Log'!$A$4:$A$369,">="&$A41,'Daily Log'!$A$4:$A$369,"<="&$A41+6)) | L41: =IFERROR(E41/J41,"") | M41: =IFERROR(H41/E41*1000,"")
A42: =A41+7 | C42: =IF(OR(B42="",B41=""),"",B42-B41) | D42: =IF(OR(B42="",B41=""),"",IFERROR((B42-B41)/B41,"")) | J42: =IF($A42>TODAY(),"",SUMIFS('Daily Log'!$C$4:$C$369,'Daily Log'!$A$4:$A$369,">="&$A42,'Daily Log'!$A$4:$A$369,"<="&$A42+6)) | K42: =IF($A42>TODAY(),"",SUMIFS('Daily Log'!$D$4:$D$369,'Daily Log'!$A$4:$A$369,">="&$A42,'Daily Log'!$A$4:$A$369,"<="&$A42+6)) | L42: =IFERROR(E42/J42,"") | M42: =IFERROR(H42/E42*1000,"")
A43: =A42+7 | C43: =IF(OR(B43="",B42=""),"",B43-B42) | D43: =IF(OR(B43="",B42=""),"",IFERROR((B43-B42)/B42,"")) | J43: =IF($A43>TODAY(),"",SUMIFS('Daily Log'!$C$4:$C$369,'Daily Log'!$A$4:$A$369,">="&$A43,'Daily Log'!$A$4:$A$369,"<="&$A43+6)) | K43: =IF($A43>TODAY(),"",SUMIFS('Daily Log'!$D$4:$D$369,'Daily Log'!$A$4:$A$369,">="&$A43,'Daily Log'!$A$4:$A$369,"<="&$A43+6)) | L43: =IFERROR(E43/J43,"") | M43: =IFERROR(H43/E43*1000,"")
A44: =A43+7 | C44: =IF(OR(B44="",B43=""),"",B44-B43) | D44: =IF(OR(B44="",B43=""),"",IFERROR((B44-B43)/B43,"")) | J44: =IF($A44>TODAY(),"",SUMIFS('Daily Log'!$C$4:$C$369,'Daily Log'!$A$4:$A$369,">="&$A44,'Daily Log'!$A$4:$A$369,"<="&$A44+6)) | K44: =IF($A44>TODAY(),"",SUMIFS('Daily Log'!$D$4:$D$369,'Daily Log'!$A$4:$A$369,">="&$A44,'Daily Log'!$A$4:$A$369,"<="&$A44+6)) | L44: =IFERROR(E44/J44,"") | M44: =IFERROR(H44/E44*1000,"")
A45: =A44+7 | C45: =IF(OR(B45="",B44=""),"",B45-B44) | D45: =IF(OR(B45="",B44=""),"",IFERROR((B45-B44)/B44,"")) | J45: =IF($A45>TODAY(),"",SUMIFS('Daily Log'!$C$4:$C$369,'Daily Log'!$A$4:$A$369,">="&$A45,'Daily Log'!$A$4:$A$369,"<="&$A45+6)) | K45: =IF($A45>TODAY(),"",SUMIFS('Daily Log'!$D$4:$D$369,'Daily Log'!$A$4:$A$369,">="&$A45,'Daily Log'!$A$4:$A$369,"<="&$A45+6)) | L45: =IFERROR(E45/J45,"") | M45: =IFERROR(H45/E45*1000,"")
A46: =A45+7 | C46: =IF(OR(B46="",B45=""),"",B46-B45) | D46: =IF(OR(B46="",B45=""),"",IFERROR((B46-B45)/B45,"")) | J46: =IF($A46>TODAY(),"",SUMIFS('Daily Log'!$C$4:$C$369,'Daily Log'!$A$4:$A$369,">="&$A46,'Daily Log'!$A$4:$A$369,"<="&$A46+6)) | K46: =IF($A46>TODAY(),"",SUMIFS('Daily Log'!$D$4:$D$369,'Daily Log'!$A$4:$A$369,">="&$A46,'Daily Log'!$A$4:$A$369,"<="&$A46+6)) | L46: =IFERROR(E46/J46,"") | M46: =IFERROR(H46/E46*1000,"")
A47: =A46+7 | C47: =IF(OR(B47="",B46=""),"",B47-B46) | D47: =IF(OR(B47="",B46=""),"",IFERROR((B47-B46)/B46,"")) | J47: =IF($A47>TODAY(),"",SUMIFS('Daily Log'!$C$4:$C$369,'Daily Log'!$A$4:$A$369,">="&$A47,'Daily Log'!$A$4:$A$369,"<="&$A47+6)) | K47: =IF($A47>TODAY(),"",SUMIFS('Daily Log'!$D$4:$D$369,'Daily Log'!$A$4:$A$369,">="&$A47,'Daily Log'!$A$4:$A$369,"<="&$A47+6)) | L47: =IFERROR(E47/J47,"") | M47: =IFERROR(H47/E47*1000,"")
A48: =A47+7 | C48: =IF(OR(B48="",B47=""),"",B48-B47) | D48: =IF(OR(B48="",B47=""),"",IFERROR((B48-B47)/B47,"")) | J48: =IF($A48>TODAY(),"",SUMIFS('Daily Log'!$C$4:$C$369,'Daily Log'!$A$4:$A$369,">="&$A48,'Daily Log'!$A$4:$A$369,"<="&$A48+6)) | K48: =IF($A48>TODAY(),"",SUMIFS('Daily Log'!$D$4:$D$369,'Daily Log'!$A$4:$A$369,">="&$A48,'Daily Log'!$A$4:$A$369,"<="&$A48+6)) | L48: =IFERROR(E48/J48,"") | M48: =IFERROR(H48/E48*1000,"")
... A72: =A71+7 | C72: =IF(OR(B72="",B71=""),"",B72-B71) | D72: =IF(OR(B72="",B71=""),"",IFERROR((B72-B71)/B71,"")) | J72: =IF($A72>TODAY(),"",SUMIFS('Daily Log'!$C$4:$C$369,'Daily Log'!$A$4:$A$369,">="&$A72,'Daily Log'!$A$4:$A$369,"<="&$A72+6)) | K72: =IF($A72>TODAY(),"",SUMIFS('Daily Log'!$D$4:$D$369,'Daily Log'!$A$4:$A$369,">="&$A72,'Daily Log'!$A$4:$A$369,"<="&$A72+6)) | L72: =IFERROR(E72/J72,"") | M72: =IFERROR(H72/E72*1000,"")

Sheet Cheat Sheet
A1: DEMO · CHEAT SHEET — what your numbers are telling you · SAMPLE DATA — REFERENCE ONLY
A2: Every number in this sheet has one job: to tell you which single thing to fix next.
A4: HOW TO READ YOUR NUMBERS
B5: Your business is a chain. Content gets you seen. Stories build trust. Opener DMs start conversations. Follow-ups rescue the ones that stalled. Replies become pitches, pitches become booked calls, booked calls become clients.
B6: Every link has a rate. When the money is down, one link broke — and the rates tell you exactly which one. That is the entire point of this sheet: stop guessing, fix one thing.
B7: Rule of thumb: fix the earliest broken link first. Working on your close rate while your reply rate is broken just means closing a smaller number of people.
A9: HEALTHY RANGES — edit these as you learn what's true for your clients
A10: Rate | B10: What it's measuring | C10: Healthy floor | D10: Healthy ceiling
A11: Reply rate | B11: Replies ÷ DMs sent — Whether your opener is worth answering. Nothing downstream can beat this number. | C11: 0.1 | D11: 0.25
A12: Pitch rate | B12: Calls pitched ÷ replies — Whether you actually ask. This is the most common place the whole thing quietly dies. | C12: 0.3 | D12: 0.6
A13: Book rate | B13: Calls booked ÷ pitched — Whether the ask lands when you make it. | C13: 0.2 | D13: 0.4
A14: Show rate | B14: Calls showed ÷ booked — Whether the booking was real. This is a confirmation problem, almost never a booking problem. | C14: 0.6 | D14: 0.85
A15: Close rate | B15: Closes ÷ showed — The offer and the call itself — but only for the people who actually turned up. | C15: 0.2 | D15: 0.4
B16: These are The Called's working numbers, not gospel — they are cream cells because they are yours to change. The KPI Dashboard colours your rates against the FLOOR column: edit a floor here and the dashboard re-grades itself. Once you have enough client history, replace these with what you actually see.
A18: THE FIVE RATES — where the money actually leaks
A19: REPLY RATE — replies ÷ dms sent
A20: Measures | B20: Whether your opener is worth answering. Nothing downstream can beat this number.
A21: If it's low | B21: Your opener reads like a pitch, or you're messaging people who have never seen you. Cold list, or a first line about you instead of them.
A22: Do this | B22: Rewrite the first line so it's about them — something specific from their profile or content. Warm the list first: watch stories and reply to posts for 2–3 days before the DM. Change ONE thing and give it 50 DMs before you judge it.
A23: If it's high | B23: Good — but check your pitch rate. A high reply rate with a low pitch rate means you're being liked, not hired. Pleasant conversations are not pipeline.
A25: PITCH RATE — calls pitched ÷ replies
A26: Measures | B26: Whether you actually ask. This is the most common place the whole thing quietly dies.
A27: If it's low | B27: You're chatting. Either you're scared of the ask, or you don't have a clean line to get from conversation to call.
A28: Do this | B28: Decide the ask before you open the conversation. Two exchanges, then transition. Write one transition line, save it, and use it every time until it feels boring.
A29: If it's high | B29: Check your book rate. If you're pitching almost everyone and few are booking, you're asking before you've earned it.
A31: BOOK RATE — calls booked ÷ pitched
A32: Measures | B32: Whether the ask lands when you make it.
A33: If it's low | B33: Three usual causes: asking too early, an unclear offer, or pitching people who were never going to buy.
A34: Do this | B34: Qualify before you ask — do they actually have the problem you solve, and can they pay? Make the call sound like a specific outcome, not “a quick chat”. Offer two times, not an open calendar.
A35: If it's high | B35: Your ask works. The bottleneck is upstream — send more DMs.
A37: SHOW RATE — calls showed ÷ booked
A38: Measures | B38: Whether the booking was real. This is a confirmation problem, almost never a booking problem.
A39: If it's low | B39: Most no-shows booked in a moment of interest and then forgot. The gap between booking and call is where it died.
A40: Do this | B40: Book inside 48 hours — the further out, the colder. Confirm within an hour of booking and ask them to reply. Remind 24 hours before and again the morning of. A confirmation they don't reply to isn't a confirmation.
A41: If it's high | B41: Your bookings are real. Push volume upstream. Over a single week this can read above 100% — a call booked on Friday gets shown on Monday, so inside a 7-day window the shows can outnumber the bookings. It is not a broken number. Judge show rate on the month or all-time column, never on one week.
A43: CLOSE RATE — closes ÷ showed
A44: Measures | B44: The offer and the call itself — but only for the people who actually turned up.
A45: If it's low | B45: Check book rate first. High book rate plus low close rate is a qualification problem, not a closing problem — you're booking the wrong people, and no call script fixes that. If qualification is fine, it's the call structure or the price framing.
A46: Do this | B46: Fix who's showing up before you fix the call. Then: diagnose longer before you present, and get the money objection on the table early rather than at the end.
A47: If it's high | B47: Your offer works and the right people are showing. Every extra DM is now worth real money — look at Cash per 100 DMs and act on it.
...

Sheet Weekly Rollup
A1: DEMO · WEEKLY ROLLUP — your last 13 weeks · SAMPLE DATA — REFERENCE ONLY
A2: All automatic. The dashboard charts read from here. Nothing to fill in.
A3: Week Starting | B3: Week | C3: Days Logged | D3: Reels / Posts | E3: Stories | F3: Opener DMs | G3: Follow-Up DMs | H3: Total DMs Sent | I3: Replies | J3: Calls Pitched | K3: Calls Booked | L3: Calls Showed | M3: Closes | N3: Cash Collected | O3: Revenue | P3: Reply Rate | Q3: Pitch Rate | R3: Book Rate | S3: Show Rate | T3: Close Rate
A4: =TODAY()-WEEKDAY(TODAY(),2)+1-84 | B4: =IF(A4="","",TEXT(A4,"d mmm")) | C4: =IF($A4<Setup!$C$9,"",SUMIFS('Daily Log'!$Q$4:$Q$369,'Daily Log'!$A$4:$A$369,">="&$A4,'Daily Log'!$A$4:$A$369,"<="&$A4+6)) | D4: =IF($A4<Setup!$C$9,"",SUMIFS('Daily Log'!$C$4:$C$369,'Daily Log'!$A$4:$A$369,">="&$A4,'Daily Log'!$A$4:$A$369,"<="&$A4+6)) | E4: =IF($A4<Setup!$C$9,"",SUMIFS('Daily Log'!$D$4:$D$369,'Daily Log'!$A$4:$A$369,">="&$A4,'Daily Log'!$A$4:$A$369,"<="&$A4+6)) | F4: =IF($A4<Setup!$C$9,"",SUMIFS('Daily Log'!$E$4:$E$369,'Daily Log'!$A$4:$A$369,">="&$A4,'Daily Log'!$A$4:$A$369,"<="&$A4+6)) | G4: =IF($A4<Setup!$C$9,"",SUMIFS('Daily Log'!$F$4:$F$369,'Daily Log'!$A$4:$A$369,">="&$A4,'Daily Log'!$A$4:$A$369,"<="&$A4+6)) | H4: =IF($A4<Setup!$C$9,"",IFERROR(F4+G4,"")) | I4: =IF($A4<Setup!$C$9,"",SUMIFS('Daily Log'!$G$4:$G$369,'Daily Log'!$A$4:$A$369,">="&$A4,'Daily Log'!$A$4:$A$369,"<="&$A4+6)) | J4: =IF($A4<Setup!$C$9,"",SUMIFS('Daily Log'!$H$4:$H$369,'Daily Log'!$A$4:$A$369,">="&$A4,'Daily Log'!$A$4:$A$369,"<="&$A4+6)) | K4: =IF($A4<Setup!$C$9,"",SUMIFS('Daily Log'!$I$4:$I$369,'Daily Log'!$A$4:$A$369,">="&$A4,'Daily Log'!$A$4:$A$369,"<="&$A4+6)) | L4: =IF($A4<Setup!$C$9,"",SUMIFS('Daily Log'!$J$4:$J$369,'Daily Log'!$A$4:$A$369,">="&$A4,'Daily Log'!$A$4:$A$369,"<="&$A4+6)) | M4: =IF($A4<Setup!$C$9,"",SUMIFS('Daily Log'!$K$4:$K$369,'Daily Log'!$A$4:$A$369,">="&$A4,'Daily Log'!$A$4:$A$369,"<="&$A4+6)) | N4: =IF($A4<Setup!$C$9,"",SUMIFS('Daily Log'!$L$4:$L$369,'Daily Log'!$A$4:$A$369,">="&$A4,'Daily Log'!$A$4:$A$369,"<="&$A4+6)) | O4: =IF($A4<Setup!$C$9,"",SUMIFS('Daily Log'!$M$4:$M$369,'Daily Log'!$A$4:$A$369,">="&$A4,'Daily Log'!$A$4:$A$369,"<="&$A4+6)) | P4: =IFERROR(I4/H4,"") | Q4: =IFERROR(J4/I4,"") | R4: =IFERROR(K4/J4,"") | S4: =IFERROR(L4/K4,"") | T4: =IFERROR(M4/L4,"")
